Workbook

Sheet AI伪装|AIFeign
A1: ID | B1: AI昵称 | C1: 等级 | D1: 今日已获得经验 | E1: 经验值 | F1: 势力 | G1: 性别 | H1: 形象Id | I1: 声望 | J1: 段位积分 | K1: 2v2楚军胜场 | L1: 2v2楚军总场数 | M1: 2v2楚军逃跑场数 | N1: 2v2汉军胜场 | O1: 2v2汉军总场数 | P1: 2v2汉军逃跑场数 | Q1: Identity主公胜场 | R1: Identity主公总场数 | S1: Identity主公逃跑场数 | T1: Identity先公胜场 | U1: Identity先公总场数 | V1: Identity先公逃跑场数 | W1: Identity潜龙胜场 | X1: Identity潜龙总场数 | Y1: Identity潜龙逃跑场数 | Z1: Identity明主胜场 | AA1: Identity明主总场数 | AB1: Identity明主逃跑场数 | AC1: Identity忠臣胜场 | AD1: Identity忠臣总场数 | AE1: Identity忠臣逃跑场数 | AF1: Identity储君胜场 | AG1: Identity储君总场数 | AH1: Identity储君逃跑场数 | AI1: Identity上将胜场 | AJ1: Identity上将总场数 | AK1: Identity上将逃跑场数 | AL1: Identity禁军胜场 | AM1: Identity禁军总场数 | AN1: Identity禁军逃跑场数 | AO1: Identity反贼胜场 | AP1: Identity反贼总场数 | AQ1: Identity反贼逃跑场数 | AR1: Identity盟主胜场 | AS1: Identity盟主总场数 | AT1: Identity盟主逃跑场数 | AU1: Identity军师胜场 | AV1: Identity军师总场数 | AW1: Identity军师逃跑场数 | AX1: Identity先锋胜场 | AY1: Identity先锋总场数 | AZ1: Identity先锋逃跑场数 | BA1: Identity内奸胜场 | BB1: Identity内奸总场数 | BC1: Identity内奸逃跑场数 | BD1: Identity黄巾胜场 | BE1: Identity黄巾总场数 | BF1: Identity黄巾逃跑场数 | BG1: Identity刺客胜场 | BH1: Identity刺客总场数 | BI1: Identity刺客逃跑场数 | BJ1: Identity伪帝胜场 | BK1: Identity伪帝总场数 | BL1: Identity伪帝逃跑场数
A2: int | B2: string | C2: int | D2: int | E2: int | F2: int | G2: int | H2: int | I2: int | J2: int | K2: int | L2: int | M2: int | N2: int | O2: int | P2: int | Q2: int | R2: int | S2: int | T2: int | U2: int | V2: int | W2: int | X2: int | Y2: int | Z2: int | AA2: int | AB2: int | AC2: int | AD2: int | AE2: int | AF2: int | AG2: int | AH2: int | AI2: int | AJ2: int | AK2: int | AL2: int | AM2: int | AN2: int | AO2: int | AP2: int | AQ2: int | AR2: int | AS2: int | AT2: int | AU2: int | AV2: int | AW2: int | AX2: int | AY2: int | AZ2: int | BA2: int | BB2: int | BC2: int | BD2: int | BE2: int | BF2: int | BG2: int | BH2: int | BI2: int | BJ2: int | BK2: int | BL2: int
A3: Id | B3: AIName | C3: Level | D3: TodayGetExp | E3: Exp | F3: Country | G3: Sex | H3: ImageItemId | I3: Prestige | J3: DunScore | K3: ChuJunWinCount | L3: ChuJunTotalCount | M3: ChuJunEscapeCount | N3: HanJunWinCount | O3: HanJunTotalCount | P3: HanJunEscapeCount | Q3: ZhuGongWinCount | R3: ZhuGongTotalCount | S3: ZhuGongEscapeCount | T3: XianZhuWinCount | U3: XianZhuTotalCount | V3: XianZhuEscapeCount | W3: QianLongWinCount | X3: QianLongTotalCount | Y3: QianLongEscapeCount | Z3: MingZhuWinCount | AA3: MingZhuTotalCount | AB3: MingZhuEscapeCount | AC3: ZhongChenWinCount | AD3: ZhongChenTotalCount | AE3: ZhongChenEscapeCount | AF3: TaiZiWinCount | AG3: TaiZiTotalCount | AH3: TaiZiEscapeCount | AI3: ShangJiangWinCount | AJ3: ShangJiangTotalCount | AK3: ShangJiangEscapeCount | AL3: JinJunWinCount | AM3: JinJunTotalCount | AN3: JinJunEscapeCount | AO3: FanZeiWinCount | AP3: FanZeiTotalCount | AQ3: FanZeiEscapeCount | AR3: MengZhuWinCount | AS3: MengZhuTotalCount | AT3: MengZhuEscapeCount | AU3: JunShiWinCount | AV3: JunShiTotalCount | AW3: JunShiEscapeCount | AX3: XianFengWinCount | AY3: XianFengTotalCount | AZ3: XianFengEscapeCount | BA3: NeiJianWinCount | BB3: NeiJianTotalCount | BC3: NeiJianEscapeCount | BD3: HuangJinWinCount | BE3: HuangJinTotalCount | BF3: HuangJinEscapeCount | BG3: CiKeWinCount | BH3: CiKeTotalCount | BI3: CiKeEscapeCount | BJ3: WeiDiWinCount | BK3: WeiDiTotalCount | BL3: WeiDiEscapeCount
A4: server/client | B4: server/client | C4: server/client | D4: server/client | E4: server/client | F4: server/client | G4: server/client | H4: server/client | I4: server/client | J4: server/client | K4: server | L4: server | M4: server | N4: server | O4: server | P4: server | Q4: server | R4: server | S4: server | T4: server | U4: server | V4: server | W4: server | X4: server | Y4: server | Z4: server | AA4: server | AB4: server | AC4: server | AD4: server | AE4: server | AF4: server | AG4: server | AH4: server | AI4: server | AJ4: server | AK4: server | AL4: server | AM4: server | AN4: server | AO4: server | AP4: server | AQ4: server | AR4: server | AS4: server | AT4: server | AU4: server | AV4: server | AW4: server | AX4: server | AY4: server | AZ4: server | BA4: server | BB4: server | BC4: server | BD4: server | BE4: server | BF4: server | BG4: server | BH4: server | BI4: server | BJ4: server | BK4: server | BL4: server
A5: 1001 | B5: 灵智-曹操 | C5: =RANDBETWEEN(10,50) -> 10 | D5: =RANDBETWEEN(0,1000) -> 886 | E5: =RANDBETWEEN(INDEX(Sheet1!$G:$G,MATCH('AI伪装|AIFeign'!C5,Sheet1!$E$2:$E$999,0)),INDEX(Sheet1!$G:$G,MATCH('AI伪装|AIFeign'!C5+1,Sheet1!$E:$E,0))) -> 196 | F5: =RANDBETWEEN(1,7) -> 4 | G5: 1 | H5: =IF(INDEX(Sheet1!$A$1:$A$40,MATCH(RANDBETWEEN(1,40),Sheet1!$B$1:$B$40,0))<>1020305,INDEX(Sheet1!$A$1:$A$40,MATCH(RANDBETWEEN(1,40),Sheet1!$B$1:$B$40,0)),1020303) -> 1020303 | I5: =RANDBETWEEN(-200,2000) -> 1791 | J5: =RANDBETWEEN(20,20000) -> 6349 | K5: =RANDBETWEEN(10,L5) -> 28 | L5: =RANDBETWEEN(10,600) -> 341 | M5: =RANDBETWEEN(0,L5*0.3) -> 9 | N5: =RANDBETWEEN(0,O5) -> 87 | O5: =MAX(RANDBETWEEN(L5-50,L5+50),0) -> 351 | P5: =RANDBETWEEN(0,O5*0.3) -> 25 | Q5: =RANDBETWEEN(10,R5) -> 58 | R5: =RANDBETWEEN(10,100) -> 58 | S5: =RANDBETWEEN(0,R5*0.3) -> 10 | T5: =RANDBETWEEN(10,U5) -> 28 | U5: =RANDBETWEEN(10,100) -> 66 | V5: =RANDBETWEEN(0,U5*0.3) -> 18 | W5: =RANDBETWEEN(10,X5) -> 23 | X5: =RANDBETWEEN(10,100) -> 28 | Y5: =RANDBETWEEN(0,X5*0.3) -> 7 | Z5: =RANDBETWEEN(10,AA5) -> 35 | AA5: =RANDBETWEEN(10,100) -> 72 | AB5: =RANDBETWEEN(0,AA5*0.3) -> 15 | AC5: =RANDBETWEEN(0,AD5) -> 76 | AD5: =RANDBETWEEN(R5*2-R5,R5*2+R5) -> 148 | AE5: =RANDBETWEEN(0,AD5*0.3) -> 26 | AF5: =RANDBETWEEN(10,AG5) -> 11 | AG5: =RANDBETWEEN(10,50) -> 12 | AH5: =RANDBETWEEN(0,AG5*0.3) -> 2 | AI5: =RANDBETWEEN(10,AJ5) -> 10 | AJ5: =RANDBETWEEN(10,50) -> 22 | AK5: =RANDBETWEEN(0,AJ5*0.3) -> 2 | AL5: =RANDBETWEEN(10,AM5) -> 11 | AM5: =RANDBETWEEN(10,50) -> 23 | AN5: =RANDBETWEEN(0,AM5*0.3) -> 4 | AO5: =RANDBETWEEN(10,AP5) -> 340 | AP5: =RANDBETWEEN(AD5*4-AD5,AD5*4+AD5) -> 526 | AQ5: =RANDBETWEEN(0,AP5*0.3) -> 15 | AR5: =RANDBETWEEN(10,AS5) -> 20 | AS5: =RANDBETWEEN(10,50) -> 41 | AT5: =RANDBETWEEN(0,AS5*0.3) -> 8 | AU5: =RANDBETWEEN(10,AV5) -> 35 | AV5: =RANDBETWEEN(10,50) -> 46 | AW5: =RANDBETWEEN(0,AV5*0.3) -> 7 | AX5: =RANDBETWEEN(10,AY5) -> 15 | AY5: =RANDBETWEEN(10,50) -> 17 | AZ5: =RANDBETWEEN(0,AY5*0.3) -> 1 | BA5: =RANDBETWEEN(10,BB5) -> 27 | BB5: =RANDBETWEEN(10,50) -> 27 | BC5: =RANDBETWEEN(0,BB5*0.3) -> 8 | BD5: =RANDBETWEEN(10,BE5) -> 118 | BE5: =RANDBETWEEN(10,200) -> 200 | BF5: =RANDBETWEEN(0,BE5*0.3) -> 33 | BG5: =RANDBETWEEN(10,BH5) -> 136 | BH5: =RANDBETWEEN(10,200) -> 136 | BI5: =RANDBETWEEN(0,BH5*0.3) -> 38 | BJ5: =RANDBETWEEN(10,BK5) -> 45 | BK5: =RANDBETWEEN(10,80) -> 57 | BL5: =RANDBETWEEN(0,BK5*0.3) -> 16
A6: 1002 | B6: 灵智-郭嘉 | C6: =RANDBETWEEN(10,50) -> 33 | D6: =RANDBETWEEN(0,1000) -> 135 | E6: =RANDBETWEEN(INDEX(Sheet1!$G:$G,MATCH('AI伪装|AIFeign'!C6,Sheet1!$E$2:$E$999,0)),INDEX(Sheet1!$G:$G,MATCH('AI伪装|AIFeign'!C6+1,Sheet1!$E:$E,0))) -> 5257 | F6: =RANDBETWEEN(1,7) -> 2 | G6: 1 | H6: =IF(INDEX(Sheet1!$A$1:$A$40,MATCH(RANDBETWEEN(1,40),Sheet1!$B$1:$B$40,0))<>1020305,INDEX(Sheet1!$A$1:$A$40,MATCH(RANDBETWEEN(1,40),Sheet1!$B$1:$B$40,0)),1020303) -> 1020301 | I6: =RANDBETWEEN(-200,2000) -> 715 | J6: =RANDBETWEEN(20,20000) -> 7394 | K6: =RANDBETWEEN(10,L6) -> 486 | L6: =RANDBETWEEN(10,600) -> 558 | M6: =RANDBETWEEN(0,L6*0.3) -> 7 | N6: =RANDBETWEEN(0,O6) -> 3 | O6: =MAX(RANDBETWEEN(L6-50,L6+50),0) -> 513 | P6: =RANDBETWEEN(0,O6*0.3) -> 130 | Q6: =RANDBETWEEN(10,R6) -> 27 | R6: =RANDBETWEEN(10,100) -> 35 | S6: =RANDBETWEEN(0,R6*0.3) -> 4 | T6: =RANDBETWEEN(10,U6) -> 13 | U6: =RANDBETWEEN(10,100) -> 51 | V6: =RANDBETWEEN(0,U6*0.3) -> 2 | W6: =RANDBETWEEN(10,X6) -> 12 | X6: =RANDBETWEEN(10,100) -> 17 | Y6: =RANDBETWEEN(0,X6*0.3) -> 5 | Z6: =RANDBETWEEN(10,AA6) -> 48 | AA6: =RANDBETWEEN(10,100) -> 95 | AB6: =RANDBETWEEN(0,AA6*0.3) -> 12 | AC6: =RANDBETWEEN(0,AD6) -> 31 | AD6: =RANDBETWEEN(R6*2-R6,R6*2+R6) -> 36 | AE6: =RANDBETWEEN(0,AD6*0.3) -> 4 | AF6: =RANDBETWEEN(10,AG6) -> 19 | AG6: =RANDBETWEEN(10,50) -> 34 | AH6: =RANDBETWEEN(0,AG6*0.3) -> 2 | AI6: =RANDBETWEEN(10,AJ6) -> 29 | AJ6: =RANDBETWEEN(10,50) -> 29 | AK6: =RANDBETWEEN(0,AJ6*0.3) -> 1 | AL6: =RANDBETWEEN(10,AM6) -> 41 | AM6: =RANDBETWEEN(10,50) -> 44 | AN6: =RANDBETWEEN(0,AM6*0.3) -> 2 | AO6: =RANDBETWEEN(10,AP6) -> 41 | AP6: =RANDBETWEEN(AD6*4-AD6,AD6*4+AD6) -> 142 | AQ6: =RANDBETWEEN(0,AP6*0.3) -> 12 | AR6: =RANDBETWEEN(10,AS6) -> 25 | AS6: =RANDBETWEEN(10,50) -> 25 | AT6: =RANDBETWEEN(0,AS6*0.3) -> 2 | AU6: =RANDBETWEEN(10,AV6) -> 10 | AV6: =RANDBETWEEN(10,50) -> 22 | AW6: =RANDBETWEEN(0,AV6*0.3) -> 3 | AX6: =RANDBETWEEN(10,AY6) -> 10 | AY6: =RANDBETWEEN(10,50) -> 48 | AZ6: =RANDBETWEEN(0,AY6*0.3) -> 5 | BA6: =RANDBETWEEN(10,BB6) -> 12 | BB6: =RANDBETWEEN(10,50) -> 28 | BC6: =RANDBETWEEN(0,BB6*0.3) -> 1 | BD6: =RANDBETWEEN(10,BE6) -> 18 | BE6: =RANDBETWEEN(10,200) -> 92 | BF6: =RANDBETWEEN(0,BE6*0.3) -> 21 | BG6: =RANDBETWEEN(10,BH6) -> 92 | BH6: =RANDBETWEEN(10,200) -> 93 | BI6: =RANDBETWEEN(0,BH6*0.3) -> 11 | BJ6: =RANDBETWEEN(10,BK6) -> 10 | BK6: =RANDBETWEEN(10,80) -> 20 | BL6: =RANDBETWEEN(0,BK6*0.3) -> 2
A7: 1003 | B7: 灵智-张辽 | C7: =RANDBETWEEN(10,50) -> 29 | D7: =RANDBETWEEN(0,1000) -> 402 | E7: =RANDBETWEEN(INDEX(Sheet1!$G:$G,MATCH('AI伪装|AIFeign'!C7,Sheet1!$E$2:$E$999,0)),INDEX(Sheet1!$G:$G,MATCH('AI伪装|AIFeign'!C7+1,Sheet1!$E:$E,0))) -> 3113 | F7: =RANDBETWEEN(1,7) -> 7 | G7: 1 | H7: =IF(INDEX(Sheet1!$A$1:$A$40,MATCH(RANDBETWEEN(1,40),Sheet1!$B$1:$B$40,0))<>1020305,INDEX(Sheet1!$A$1:$A$40,MATCH(RANDBETWEEN(1,40),Sheet1!$B$1:$B$40,0)),1020303) -> 1020306 | I7: =RANDBETWEEN(-200,2000) -> 667 | J7: =RANDBETWEEN(20,20000) -> 211 | K7: =RANDBETWEEN(10,L7) -> 107 | L7: =RANDBETWEEN(10,600) -> 306 | M7: =RANDBETWEEN(0,L7*0.3) -> 19 | N7: =RANDBETWEEN(0,O7) -> 229 | O7: =MAX(RANDBETWEEN(L7-50,L7+50),0) -> 296 | P7: =RANDBETWEEN(0,O7*0.3) -> 39 | Q7: =RANDBETWEEN(10,R7) -> 14 | R7: =RANDBETWEEN(10,100) -> 18 | S7: =RANDBETWEEN(0,R7*0.3) -> 0 | T7: =RANDBETWEEN(10,U7) -> 62 | U7: =RANDBETWEEN(10,100) -> 100 | V7: =RANDBETWEEN(0,U7*0.3) -> 30 | W7: =RANDBETWEEN(10,X7) -> 34 | X7: =RANDBETWEEN(10,100) -> 57 | Y7: =RANDBETWEEN(0,X7*0.3) -> 17 | Z7: =RANDBETWEEN(10,AA7) -> 31 | AA7: =RANDBETWEEN(10,100) -> 43 | AB7: =RANDBETWEEN(0,AA7*0.3) -> 4 | AC7: =RANDBETWEEN(0,AD7) -> 12 | AD7: =RANDBETWEEN(R7*2-R7,R7*2+R7) -> 20 | AE7: =RANDBETWEEN(0,AD7*0.3) -> 2 | AF7: =RANDBETWEEN(10,AG7) -> 14 | AG7: =RANDBETWEEN(10,50) -> 36 | AH7: =RANDBETWEEN(0,AG7*0.3) -> 1 | AI7: =RANDBETWEEN(10,AJ7) -> 14 | AJ7: =RANDBETWEEN(10,50) -> 22 | AK7: =RANDBETWEEN(0,AJ7*0.3) -> 3 | AL7: =RANDBETWEEN(10,AM7) -> 10 | AM7: =RANDBETWEEN(10,50) -> 25 | AN7: =RANDBETWEEN(0,AM7*0.3) -> 1 | AO7: =RANDBETWEEN(10,AP7) -> 48 | AP7: =RANDBETWEEN(AD7*4-AD7,AD7*4+AD7) -> 88 | AQ7: =RANDBETWEEN(0,AP7*0.3) -> 24 | AR7: =RANDBETWEEN(10,AS7) -> 34 | AS7: =RANDBETWEEN(10,50) -> 38 | AT7: =RANDBETWEEN(0,AS7*0.3) -> 10 | AU7: =RANDBETWEEN(10,AV7) -> 30 | AV7: =RANDBETWEEN(10,50) -> 49 | AW7: =RANDBETWEEN(0,AV7*0.3) -> 10 | AX7: =RANDBETWEEN(10,AY7) -> 41 | AY7: =RANDBETWEEN(10,50) -> 50 | AZ7: =RANDBETWEEN(0,AY7*0.3) -> 10 | BA7: =RANDBETWEEN(10,BB7) -> 18 | BB7: =RANDBETWEEN(10,50) -> 18 | BC7: =RANDBETWEEN(0,BB7*0.3) -> 3 | BD7: =RANDBETWEEN(10,BE7) -> 110 | BE7: =RANDBETWEEN(10,200) -> 199 | BF7: =RANDBETWEEN(0,BE7*0.3) -> 40 | BG7: =RANDBETWEEN(10,BH7) -> 81 | BH7: =RANDBETWEEN(10,200) -> 197 | BI7: =RANDBETWEEN(0,BH7*0.3) -> 31 | BJ7: =RANDBETWEEN(10,BK7) -> 11 | BK7: =RANDBETWEEN(10,80) -> 37 | BL7: =RANDBETWEEN(0,BK7*0.3) -> 8
A8: 1004 | B8: 灵智-甄姬 | C8: =RANDBETWEEN(10,50) -> 13 | D8: =RANDBETWEEN(0,1000) -> 732 | E8: =RANDBETWEEN(INDEX(Sheet1!$G:$G,MATCH('AI伪装|AIFeign'!C8,Sheet1!$E$2:$E$999,0)),INDEX(Sheet1!$G:$G,MATCH('AI伪装|AIFeign'!C8+1,Sheet1!$E:$E,0))) -> 359 | F8: =RANDBETWEEN(1,7) -> 1 | G8: 2 | H8: =IF(INDEX(Sheet1!$A$1:$A$40,MATCH(RANDBETWEEN(1,40),Sheet1!$B$1:$B$40,0))<>1020305,INDEX(Sheet1!$A$1:$A$40,MATCH(RANDBETWEEN(1,40),Sheet1!$B$1:$B$40,0)),1020303) -> 1020202 | I8: =RANDBETWEEN(-200,2000) -> 829 | J8: =RANDBETWEEN(20,20000) -> 13182 | K8: =RANDBETWEEN(10,L8) -> 107 | L8: =RANDBETWEEN(10,600) -> 155 | M8: =RANDBETWEEN(0,L8*0.3) -> 1 | N8: =RANDBETWEEN(0,O8) -> 39 | O8: =MAX(RANDBETWEEN(L8-50,L8+50),0) -> 200 | P8: =RANDBETWEEN(0,O8*0.3) -> 32 | Q8: =RANDBETWEEN(10,R8) -> 12 | R8: =RANDBETWEEN(10,100) -> 30 | S8: =RANDBETWEEN(0,R8*0.3) -> 8 | T8: =RANDBETWEEN(10,U8) -> 51 | U8: =RANDBETWEEN(10,100) -> 79 | V8: =RANDBETWEEN(0,U8*0.3) -> 2 | W8: =RANDBETWEEN(10,X8) -> 46 | X8: =RANDBETWEEN(10,100) -> 75 | Y8: =RANDBETWEEN(0,X8*0.3) -> 12 | Z8: =RANDBETWEEN(10,AA8) -> 24 | AA8: =RANDBETWEEN(10,100) -> 68 | AB8: =RANDBETWEEN(0,AA8*0.3) -> 18 | AC8: =RANDBETWEEN(0,AD8) -> 82 | AD8: =RANDBETWEEN(R8*2-R8,R8*2+R8) -> 84 | AE8: =RANDBETWEEN(0,AD8*0.3) -> 6 | AF8: =RANDBETWEEN(10,AG8) -> 34 | AG8: =RANDBETWEEN(10,50) -> 43 | AH8: =RANDBETWEEN(0,AG8*0.3) -> 4 | AI8: =RANDBETWEEN(10,AJ8) -> 21 | AJ8: =RANDBETWEEN(10,50) -> 34 | AK8: =RANDBETWEEN(0,AJ8*0.3) -> 3 | AL8: =RANDBETWEEN(10,AM8) -> 10 | AM8: =RANDBETWEEN(10,50) -> 25 | AN8: =RANDBETWEEN(0,AM8*0.3) -> 6 | AO8: =RANDBETWEEN(10,AP8) -> 297 | AP8: =RANDBETWEEN(AD8*4-AD8,AD8*4+AD8) -> 385 | AQ8: =RANDBETWEEN(0,AP8*0.3) -> 86 | AR8: =RANDBETWEEN(10,AS8) -> 24 | AS8: =RANDBETWEEN(10,50) -> 47 | AT8: =RANDBETWEEN(0,AS8*0.3) -> 4 | AU8: =RANDBETWEEN(10,AV8) -> 20 | AV8: =RANDBETWEEN(10,50) -> 42 | AW8: =RANDBETWEEN(0,AV8*0.3) -> 11 | AX8: =RANDBETWEEN(10,AY8) -> 29 | AY8: =RANDBETWEEN(10,50) -> 46 | AZ8: =RANDBETWEEN(0,AY8*0.3) -> 10 | BA8: =RANDBETWEEN(10,BB8) -> 13 | BB8: =RANDBETWEEN(10,50) -> 34 | BC8: =RANDBETWEEN(0,BB8*0.3) -> 7 | BD8: =RANDBETWEEN(10,BE8) -> 23 | BE8: =RANDBETWEEN(10,200) -> 38 | BF8: =RANDBETWEEN(0,BE8*0.3) -> 0 | BG8: =RANDBETWEEN(10,BH8) -> 32 | BH8: =RANDBETWEEN(10,200) -> 100 | BI8: =RANDBETWEEN(0,BH8*0.3) -> 24 | BJ8: =RANDBETWEEN(10,BK8) -> 11 | BK8: =RANDBETWEEN(10,80) -> 13 | BL8: =RANDBETWEEN(0,BK8*0.3) -> 0
A9: 1005 | B9: 灵智-荀彧 | C9: =RANDBETWEEN(10,50) -> 22 | D9: =RANDBETWEEN(0,1000) -> 126 | E9: =RANDBETWEEN(INDEX(Sheet1!$G:$G,MATCH('AI伪装|AIFeign'!C9,Sheet1!$E$2:$E$999,0)),INDEX(Sheet1!$G:$G,MATCH('AI伪装|AIFeign'!C9+1,Sheet1!$E:$E,0))) -> 1343 | F9: =RANDBETWEEN(1,7) -> 2 | G9: 1 | H9: =IF(INDEX(Sheet1!$A$1:$A$40,MATCH(RANDBETWEEN(1,40),Sheet1!$B$1:$B$40,0))<>1020305,INDEX(Sheet1!$A$1:$A$40,MATCH(RANDBETWEEN(1,40),Sheet1!$B$1:$B$40,0)),1020303) -> 1020208 | I9: =RANDBETWEEN(-200,2000) -> 1475 | J9: =RANDBETWEEN(20,20000) -> 8648 | K9: =RANDBETWEEN(10,L9) -> 96 | L9: =RANDBETWEEN(10,600) -> 407 | M9: =RANDBETWEEN(0,L9*0.3) -> 22 | N9: =RANDBETWEEN(0,O9) -> 141 | O9: =MAX(RANDBETWEEN(L9-50,L9+50),0) -> 405 | P9: =RANDBETWEEN(0,O9*0.3) -> 102 | Q9: =RANDBETWEEN(10,R9) -> 18 | R9: =RANDBETWEEN(10,100) -> 24 | S9: =RANDBETWEEN(0,R9*0.3) -> 7 | T9: =RANDBETWEEN(10,U9) -> 21 | U9: =RANDBETWEEN(10,100) -> 87 | V9: =RANDBETWEEN(0,U9*0.3) -> 21 | W9: =RANDBETWEEN(10,X9) -> 83 | X9: =RANDBETWEEN(10,100) -> 99 | Y9: =RANDBETWEEN(0,X9*0.3) -> 21 | Z9: =RANDBETWEEN(10,AA9) -> 56 | AA9: =RANDBETWEEN(10,100) -> 90 | AB9: =RANDBETWEEN(0,AA9*0.3) -> 21 | AC9: =RANDBETWEEN(0,AD9) -> 46 | AD9: =RANDBETWEEN(R9*2-R9,R9*2+R9) -> 61 | AE9: =RANDBETWEEN(0,AD9*0.3) -> 3 | AF9: =RANDBETWEEN(10,AG9) -> 21 | AG9: =RANDBETWEEN(10,50) -> 41 | AH9: =RANDBETWEEN(0,AG9*0.3) -> 7 | AI9: =RANDBETWEEN(10,AJ9) -> 42 | AJ9: =RANDBETWEEN(10,50) -> 44 | AK9: =RANDBETWEEN(0,AJ9*0.3) -> 0 | AL9: =RANDBETWEEN(10,AM9) -> 11 | AM9: =RANDBETWEEN(10,50) -> 22 | AN9: =RANDBETWEEN(0,AM9*0.3) -> 4 | AO9: =RANDBETWEEN(10,AP9) -> 85 | AP9: =RANDBETWEEN(AD9*4-AD9,AD9*4+AD9) -> 245 | AQ9: =RANDBETWEEN(0,AP9*0.3) -> 39 | AR9: =RANDBETWEEN(10,AS9) -> 12 | AS9: =RANDBETWEEN(10,50) -> 22 | AT9: =RANDBETWEEN(0,AS9*0.3) -> 6 | AU9: =RANDBETWEEN(10,AV9) -> 32 | AV9: =RANDBETWEEN(10,50) -> 50 | AW9: =RANDBETWEEN(0,AV9*0.3) -> 11 | AX9: =RANDBETWEEN(10,AY9) -> 24 | AY9: =RANDBETWEEN(10,50) -> 30 | AZ9: =RANDBETWEEN(0,AY9*0.3) -> 8 | BA9: =RANDBETWEEN(10,BB9) -> 12 | BB9: =RANDBETWEEN(10,50) -> 15 | BC9: =RANDBETWEEN(0,BB9*0.3) -> 0 | BD9: =RANDBETWEEN(10,BE9) -> 65 | BE9: =RANDBETWEEN(10,200) -> 178 | BF9: =RANDBETWEEN(0,BE9*0.3) -> 25 | BG9: =RANDBETWEEN(10,BH9) -> 11 | BH9: =RANDBETWEEN(10,200) -> 59 | BI9: =RANDBETWEEN(0,BH9*0.3) -> 8 | BJ9: =RANDBETWEEN(10,BK9) -> 33 | BK9: =RANDBETWEEN(10,80) -> 50 | BL9: =RANDBETWEEN(0,BK9*0.3) -> 4
A10: 1006 | B10: 灵智-许褚 | C10: =RANDBETWEEN(10,50) -> 10 | D10: =RANDBETWEEN(0,1000) -> 788 | E10: =RANDBETWEEN(INDEX(Sheet1!$G:$G,MATCH('AI伪装|AIFeign'!C10,Sheet1!$E$2:$E$999,0)),INDEX(Sheet1!$G:$G,MATCH('AI伪装|AIFeign'!C10+1,Sheet1!$E:$E,0))) -> 167 | F10: =RANDBETWEEN(1,7) -> 6 | G10: 1 | H10: =IF(INDEX(Sheet1!$A$1:$A$40,MATCH(RANDBETWEEN(1,40),Sheet1!$B$1:$B$40,0))<>1020305,INDEX(Sheet1!$A$1:$A$40,MATCH(RANDBETWEEN(1,40),Sheet1!$B$1:$B$40,0)),1020303) -> 1020503 | I10: =RANDBETWEEN(-200,2000) -> 1644 | J10: =RANDBETWEEN(20,20000) -> 19051 | K10: =RANDBETWEEN(10,L10) -> 152 | L10: =RANDBETWEEN(10,600) -> 600 | M10: =RANDBETWEEN(0,L10*0.3) -> 19 | N10: =RANDBETWEEN(0,O10) -> 143 | O10: =MAX(RANDBETWEEN(L10-50,L10+50),0) -> 594 | P10: =RANDBETWEEN(0,O10*0.3) -> 96 | Q10: =RANDBETWEEN(10,R10) -> 45 | R10: =RANDBETWEEN(10,100) -> 50 | S10: =RANDBETWEEN(0,R10*0.3) -> 0 | T10: =RANDBETWEEN(10,U10) -> 33 | U10: =RANDBETWEEN(10,100) -> 60 | V10: =RANDBETWEEN(0,U10*0.3) -> 10 | W10: =RANDBETWEEN(10,X10) -> 12 | X10: =RANDBETWEEN(10,100) -> 54 | Y10: =RANDBETWEEN(0,X10*0.3) -> 12 | Z10: =RANDBETWEEN(10,AA10) -> 26 | AA10: =RANDBETWEEN(10,100) -> 88 | AB10: =RANDBETWEEN(0,AA10*0.3) -> 12 | AC10: =RANDBETWEEN(0,AD10) -> 1 | AD10: =RANDBETWEEN(R10*2-R10,R10*2+R10) -> 131 | AE10: =RANDBETWEEN(0,AD10*0.3) -> 19 | AF10: =RANDBETWEEN(10,AG10) -> 10 | AG10: =RANDBETWEEN(10,50) -> 10 | AH10: =RANDBETWEEN(0,AG10*0.3) -> 2 | AI10: =RANDBETWEEN(10,AJ10) -> 35 | AJ10: =RANDBETWEEN(10,50) -> 46 | AK10: =RANDBETWEEN(0,AJ10*0.3) -> 11 | AL10: =RANDBETWEEN(10,AM10) -> 26 | AM10: =RANDBETWEEN(10,50) -> 45 | AN10: =RANDBETWEEN(0,AM10*0.3) -> 13 | AO10: =RANDBETWEEN(10,AP10) -> 532 | AP10: =RANDBETWEEN(AD10*4-AD10,AD10*4+AD10) -> 631 | AQ10: =RANDBETWEEN(0,AP10*0.3) -> 150 | AR10: =RANDBETWEEN(10,AS10) -> 21 | AS10: =RANDBETWEEN(10,50) -> 44 | AT10: =RANDBETWEEN(0,AS10*0.3) -> 10 | AU10: =RANDBETWEEN(10,AV10) -> 27 | AV10: =RANDBETWEEN(10,50) -> 50 | AW10: =RANDBETWEEN(0,AV10*0.3) -> 4 | AX10: =RANDBETWEEN(10,AY10) -> 22 | AY10: =RANDBETWEEN(10,50) -> 25 | AZ10: =RANDBETWEEN(0,AY10*0.3) -> 5 | BA10: =RANDBETWEEN(10,BB10) -> 22 | BB10: =RANDBETWEEN(10,50) -> 26 | BC10: =RANDBETWEEN(0,BB10*0.3) -> 1 | BD10: =RANDBETWEEN(10,BE10) -> 23 | BE10: =RANDBETWEEN(10,200) -> 68 | BF10: =RANDBETWEEN(0,BE10*0.3) -> 9 | BG10: =RANDBETWEEN(10,BH10) -> 16 | BH10: =RANDBETWEEN(10,200) -> 113 | BI10: =RANDBETWEEN(0,BH10*0.3) -> 12 | BJ10: =RANDBETWEEN(10,BK10) -> 34 | BK10: =RANDBETWEEN(10,80) -> 54 | BL10: =RANDBETWEEN(0,BK10*0.3) -> 1
A11: 1007 | B11: 灵智-司马懿 | C11: =RANDBETWEEN(10,50) -> 22 | D11: =RANDBETWEEN(0,1000) -> 338 | E11: =RANDBETWEEN(INDEX(Sheet1!$G:$G,MATCH('AI伪装|AIFeign'!C11,Sheet1!$E$2:$E$999,0)),INDEX(Sheet1!$G:$G,MATCH('AI伪装|AIFeign'!C11+1,Sheet1!$E:$E,0))) -> 1286 | F11: =RANDBETWEEN(1,7) -> 5 | G11: 1 | H11: =IF(INDEX(Sheet1!$A$1:$A$40,MATCH(RANDBETWEEN(1,40),Sheet1!$B$1:$B$40,0))<>1020305,INDEX(Sheet1!$A$1:$A$40,MATCH(RANDBETWEEN(1,40),Sheet1!$B$1:$B$40,0)),1020303) -> 1020105 | I11: =RANDBETWEEN(-200,2000) -> 1075 | J11: =RANDBETWEEN(20,20000) -> 2190 | K11: =RANDBETWEEN(10,L11) -> 34 | L11: =RANDBETWEEN(10,600) -> 143 | M11: =RANDBETWEEN(0,L11*0.3) -> 10 | N11: =RANDBETWEEN(0,O11) -> 124 | O11: =MAX(RANDBETWEEN(L11-50,L11+50),0) -> 158 | P11: =RANDBETWEEN(0,O11*0.3) -> 3 | Q11: =RANDBETWEEN(10,R11) -> 28 | R11: =RANDBETWEEN(10,100) -> 69 | S11: =RANDBETWEEN(0,R11*0.3) -> 20 | T11: =RANDBETWEEN(10,U11) -> 20 | U11: =RANDBETWEEN(10,100) -> 63 | V11: =RANDBETWEEN(0,U11*0.3) -> 5 | W11: =RANDBETWEEN(10,X11) -> 10 | X11: =RANDBETWEEN(10,100) -> 17 | Y11: =RANDBETWEEN(0,X11*0.3) -> 1 | Z11: =RANDBETWEEN(10,AA11) -> 13 | AA11: =RANDBETWEEN(10,100) -> 14 | AB11: =RANDBETWEEN(0,AA11*0.3) -> 2 | AC11: =RANDBETWEEN(0,AD11) -> 139 | AD11: =RANDBETWEEN(R11*2-R11,R11*2+R11) -> 157 | AE11: =RANDBETWEEN(0,AD11*0.3) -> 42 | AF11: =RANDBETWEEN(10,AG11) -> 11 | AG11: =RANDBETWEEN(10,50) -> 27 | AH11: =RANDBETWEEN(0,AG11*0.3) -> 4 | AI11: =RANDBETWEEN(10,AJ11) -> 10 | AJ11: =RANDBETWEEN(10,50) -> 21 | AK11: =RANDBETWEEN(0,AJ11*0.3) -> 1 | AL11: =RANDBETWEEN(10,AM11) -> 15 | AM11: =RANDBETWEEN(10,50) -> 20 | AN11: =RANDBETWEEN(0,AM11*0.3) -> 4 | AO11: =RANDBETWEEN(10,AP11) -> 28 | AP11: =RANDBETWEEN(AD11*4-AD11,AD11*4+AD11) -> 705 | AQ11: =RANDBETWEEN(0,AP11*0.3) -> 165 | AR11: =RANDBETWEEN(10,AS11) -> 15 | AS11: =RANDBETWEEN(10,50) -> 32 | AT11: =RANDBETWEEN(0,AS11*0.3) -> 0 | AU11: =RANDBETWEEN(10,AV11) -> 23 | AV11: =RANDBETWEEN(10,50) -> 50 | AW11: =RANDBETWEEN(0,AV11*0.3) -> 7 | AX11: =RANDBETWEEN(10,AY11) -> 29 | AY11: =RANDBETWEEN(10,50) -> 32 | AZ11: =RANDBETWEEN(0,AY11*0.3) -> 7 | BA11: =RANDBETWEEN(10,BB11) -> 45 | BB11: =RANDBETWEEN(10,50) -> 46 | BC11: =RANDBETWEEN(0,BB11*0.3) -> 10 | BD11: =RANDBETWEEN(10,BE11) -> 22 | BE11: =RANDBETWEEN(10,200) -> 26 | BF11: =RANDBETWEEN(0,BE11*0.3) -> 4 | BG11: =RANDBETWEEN(10,BH11) -> 14 | BH11: =RANDBETWEEN(10,200) -> 28 | BI11: =RANDBETWEEN(0,BH11*0.3) -> 7 | BJ11: =RANDBETWEEN(10,BK11) -> 18 | BK11: =RANDBETWEEN(10,80) -> 45 | BL11: =RANDBETWEEN(0,BK11*0.3) -> 12
A12: 1008 | B12: 灵智-典韦 | C12: =RANDBETWEEN(10,50) -> 21 | D12: =RANDBETWEEN(0,1000) -> 307 | E12: =RANDBETWEEN(INDEX(Sheet1!$G:$G,MATCH('AI伪装|AIFeign'!C12,Sheet1!$E$2:$E$999,0)),INDEX(Sheet1!$G:$G,MATCH('AI伪装|AIFeign'!C12+1,Sheet1!$E:$E,0))) -> 1115 | F12: =RANDBETWEEN(1,7) -> 2 | G12: 1 | H12: =IF(INDEX(Sheet1!$A$1:$A$40,MATCH(RANDBETWEEN(1,40),Sheet1!$B$1:$B$40,0))<>1020305,INDEX(Sheet1!$A$1:$A$40,MATCH(RANDBETWEEN(1,40),Sheet1!$B$1:$B$40,0)),1020303) -> 1020303 | I12: =RANDBETWEEN(-200,2000) -> 1833 | J12: =RANDBETWEEN(20,20000) -> 7781 | K12: =RANDBETWEEN(10,L12) -> 90 | L12: =RANDBETWEEN(10,600) -> 264 | M12: =RANDBETWEEN(0,L12*0.3) -> 14 | N12: =RANDBETWEEN(0,O12) -> 136 | O12: =MAX(RANDBETWEEN(L12-50,L12+50),0) -> 290 | P12: =RANDBETWEEN(0,O12*0.3) -> 19 | Q12: =RANDBETWEEN(10,R12) -> 44 | R12: =RANDBETWEEN(10,100) -> 52 | S12: =RANDBETWEEN(0,R12*0.3) -> 2 | T12: =RANDBETWEEN(10,U12) -> 89 | U12: =RANDBETWEEN(10,100) -> 94 | V12: =RANDBETWEEN(0,U12*0.3) -> 25 | W12: =RANDBETWEEN(10,X12) -> 63 | X12: =RANDBETWEEN(10,100) -> 85 | Y12: =RANDBETWEEN(0,X12*0.3) -> 18 | Z12: =RANDBETWEEN(10,AA12) -> 22 | AA12: =RANDBETWEEN(10,100) -> 96 | AB12: =RANDBETWEEN(0,AA12*0.3) -> 15 | AC12: =RANDBETWEEN(0,AD12) -> 44 | AD12: =RANDBETWEEN(R12*2-R12,R12*2+R12) -> 62 | AE12: =RANDBETWEEN(0,AD12*0.3) -> 1 | AF12: =RANDBETWEEN(10,AG12) -> 29 | AG12: =RANDBETWEEN(10,50) -> 39 | AH12: =RANDBETWEEN(0,AG12*0.3) -> 11 | AI12: =RANDBETWEEN(10,AJ12) -> 31 | AJ12: =RANDBETWEEN(10,50) -> 38 | AK12: =RANDBETWEEN(0,AJ12*0.3) -> 10 | AL12: =RANDBETWEEN(10,AM12) -> 43 | AM12: =RANDBETWEEN(10,50) -> 47 | AN12: =RANDBETWEEN(0,AM12*0.3) -> 0 | AO12: =RANDBETWEEN(10,AP12) -> 67 | AP12: =RANDBETWEEN(AD12*4-AD12,AD12*4+AD12) -> 306 | AQ12: =RANDBETWEEN(0,AP12*0.3) -> 38 | AR12: =RANDBETWEEN(10,AS12) -> 39 | AS12: =RANDBETWEEN(10,50) -> 41 | AT12: =RANDBETWEEN(0,AS12*0.3) -> 3 | AU12: =RANDBETWEEN(10,AV12) -> 17 | AV12: =RANDBETWEEN(10,50) -> 21 | AW12: =RANDBETWEEN(0,AV12*0.3) -> 1 | AX12: =RANDBETWEEN(10,AY12) -> 28 | AY12: =RANDBETWEEN(10,50) -> 34 | AZ12: =RANDBETWEEN(0,AY12*0.3) -> 5 | BA12: =RANDBETWEEN(10,BB12) -> 17 | BB12: =RANDBETWEEN(10,50) -> 42 | BC12: =RANDBETWEEN(0,BB12*0.3) -> 0 | BD12: =RANDBETWEEN(10,BE12) -> 81 | BE12: =RANDBETWEEN(10,200) -> 109 | BF12: =RANDBETWEEN(0,BE12*0.3) -> 11 | BG12: =RANDBETWEEN(10,BH12) -> 85 | BH12: =RANDBETWEEN(10,200) -> 157 | BI12: =RANDBETWEEN(0,BH12*0.3) -> 35 | BJ12: =RANDBETWEEN(10,BK12) -> 15 | BK12: =RANDBETWEEN(10,80) -> 22 | BL12: =RANDBETWEEN(0,BK12*0.3) -> 6
A13: 1009 | B13: 灵智-刘备 | C13: =RANDBETWEEN(10,50) -> 40 | D13: =RANDBETWEEN(0,1000) -> 452 | E13: =RANDBETWEEN(INDEX(Sheet1!$G:$G,MATCH('AI伪装|AIFeign'!C13,Sheet1!$E$2:$E$999,0)),INDEX(Sheet1!$G:$G,MATCH('AI伪装|AIFeign'!C13+1,Sheet1!$E:$E,0))) -> 9259 | F13: =RANDBETWEEN(1,7) -> 1 | G13: 1 | H13: =IF(INDEX(Sheet1!$A$1:$A$40,MATCH(RANDBETWEEN(1,40),Sheet1!$B$1:$B$40,0))<>1020305,INDEX(Sheet1!$A$1:$A$40,MATCH(RANDBETWEEN(1,40),Sheet1!$B$1:$B$40,0)),1020303) -> 1020102 | I13: =RANDBETWEEN(-200,2000) -> 689 | J13: =RANDBETWEEN(20,20000) -> 17437 | K13: =RANDBETWEEN(10,L13) -> 302 | L13: =RANDBETWEEN(10,600) -> 463 | M13: =RANDBETWEEN(0,L13*0.3) -> 61 | N13: =RANDBETWEEN(0,O13) -> 398 | O13: =MAX(RANDBETWEEN(L13-50,L13+50),0) -> 423 | P13: =RANDBETWEEN(0,O13*0.3) -> 50 | Q13: =RANDBETWEEN(10,R13) -> 24 | R13: =RANDBETWEEN(10,100) -> 67 | S13: =RANDBETWEEN(0,R13*0.3) -> 14 | T13: =RANDBETWEEN(10,U13) -> 45 | U13: =RANDBETWEEN(10,100) -> 96 | V13: =RANDBETWEEN(0,U13*0.3) -> 16 | W13: =RANDBETWEEN(10,X13) -> 15 | X13: =RANDBETWEEN(10,100) -> 24 | Y13: =RANDBETWEEN(0,X13*0.3) -> 5 | Z13: =RANDBETWEEN(10,AA13) -> 33 | AA13: =RANDBETWEEN(10,100) -> 44 | AB13: =RANDBETWEEN(0,AA13*0.3) -> 10 | AC13: =RANDBETWEEN(0,AD13) -> 34 | AD13: =RANDBETWEEN(R13*2-R13,R13*2+R13) -> 194 | AE13: =RANDBETWEEN(0,AD13*0.3) -> 23 | AF13: =RANDBETWEEN(10,AG13) -> 10 | AG13: =RANDBETWEEN(10,50) -> 23 | AH13: =RANDBETWEEN(0,AG13*0.3) -> 6 | AI13: =RANDBETWEEN(10,AJ13) -> 20 | AJ13: =RANDBETWEEN(10,50) -> 23 | AK13: =RANDBETWEEN(0,AJ13*0.3) -> 3 | AL13: =RANDBETWEEN(10,AM13) -> 16 | AM13: =RANDBETWEEN(10,50) -> 23 | AN13: =RANDBETWEEN(0,AM13*0.3) -> 5 | AO13: =RANDBETWEEN(10,AP13) -> 146 | AP13: =RANDBETWEEN(AD13*4-AD13,AD13*4+AD13) -> 951 | AQ13: =RANDBETWEEN(0,AP13*0.3) -> 183 | AR13: =RANDBETWEEN(10,AS13) -> 14 | AS13: =RANDBETWEEN(10,50) -> 25 | AT13: =RANDBETWEEN(0,AS13*0.3) -> 3 | AU13: =RANDBETWEEN(10,AV13) -> 15 | AV13: =RANDBETWEEN(10,50) -> 20 | AW13: =RANDBETWEEN(0,AV13*0.3) -> 3 | AX13: =RANDBETWEEN(10,AY13) -> 41 | AY13: =RANDBETWEEN(10,50) -> 46 | AZ13: =RANDBETWEEN(0,AY13*0.3) -> 7 | BA13: =RANDBETWEEN(10,BB13) -> 30 | BB13: =RANDBETWEEN(10,50) -> 36 | BC13: =RANDBETWEEN(0,BB13*0.3) -> 4 | BD13: =RANDBETWEEN(10,BE13) -> 126 | BE13: =RANDBETWEEN(10,200) -> 133 | BF13: =RANDBETWEEN(0,BE13*0.3) -> 9 | BG13: =RANDBETWEEN(10,BH13) -> 63 | BH13: =RANDBETWEEN(10,200) -> 85 | BI13: =RANDBETWEEN(0,BH13*0.3) -> 1 | BJ13: =RANDBETWEEN(10,BK13) -> 21 | BK13: =RANDBETWEEN(10,80) -> 22 | BL13: =RANDBETWEEN(0,BK13*0.3) -> 3
A14: 1010 | B14: 灵智-诸葛亮 | C14: =RANDBETWEEN(10,50) -> 28 | D14: =RANDBETWEEN(0,1000) -> 538 | E14: =RANDBETWEEN(INDEX(Sheet1!$G:$G,MATCH('AI伪装|AIFeign'!C14,Sheet1!$E$2:$E$999,0)),INDEX(Sheet1!$G:$G,MATCH('AI伪装|AIFeign'!C14+1,Sheet1!$E:$E,0))) -> 2701 | F14: =RANDBETWEEN(1,7) -> 7 | G14: 1 | H14: =IF(INDEX(Sheet1!$A$1:$A$40,MATCH(RANDBETWEEN(1,40),Sheet1!$B$1:$B$40,0))<>1020305,INDEX(Sheet1!$A$1:$A$40,MATCH(RANDBETWEEN(1,40),Sheet1!$B$1:$B$40,0)),1020303) -> 1020101 | I14: =RANDBETWEEN(-200,2000) -> 1077 | J14: =RANDBETWEEN(20,20000) -> 3913 | K14: =RANDBETWEEN(10,L14) -> 106 | L14: =RANDBETWEEN(10,600) -> 174 | M14: =RANDBETWEEN(0,L14*0.3) -> 36 | N14: =RANDBETWEEN(0,O14) -> 132 | O14: =MAX(RANDBETWEEN(L14-50,L14+50),0) -> 157 | P14: =RANDBETWEEN(0,O14*0.3) -> 2 | Q14: =RANDBETWEEN(10,R14) -> 27 | R14: =RANDBETWEEN(10,100) -> 53 | S14: =RANDBETWEEN(0,R14*0.3) -> 6 | T14: =RANDBETWEEN(10,U14) -> 13 | U14: =RANDBETWEEN(10,100) -> 44 | V14: =RANDBETWEEN(0,U14*0.3) -> 11 | W14: =RANDBETWEEN(10,X14) -> 26 | X14: =RANDBETWEEN(10,100) -> 38 | Y14: =RANDBETWEEN(0,X14*0.3) -> 8 | Z14: =RANDBETWEEN(10,AA14) -> 15 | AA14: =RANDBETWEEN(10,100) -> 18 | AB14: =RANDBETWEEN(0,AA14*0.3) -> 3 | AC14: =RANDBETWEEN(0,AD14) -> 5 | AD14: =RANDBETWEEN(R14*2-R14,R14*2+R14) -> 147 | AE14: =RANDBETWEEN(0,AD14*0.3) -> 16 | AF14: =RANDBETWEEN(10,AG14) -> 31 | AG14: =RANDBETWEEN(10,50) -> 35 | AH14: =RANDBETWEEN(0,AG14*0.3) -> 4 | AI14: =RANDBETWEEN(10,AJ14) -> 15 | AJ14: =RANDBETWEEN(10,50) -> 23 | AK14: =RANDBETWEEN(0,AJ14*0.3) -> 6 | AL14: =RANDBETWEEN(10,AM14) -> 14 | AM14: =RANDBETWEEN(10,50) -> 17 | AN14: =RANDBETWEEN(0,AM14*0.3) -> 4 | AO14: =RANDBETWEEN(10,AP14) -> 342 | AP14: =RANDBETWEEN(AD14*4-AD14,AD14*4+AD14) -> 636 | AQ14: =RANDBETWEEN(0,AP14*0.3) -> 147 | AR14: =RANDBETWEEN(10,AS14) -> 26 | AS14: =RANDBETWEEN(10,50) -> 44 | AT14: =RANDBETWEEN(0,AS14*0.3) -> 2 | AU14: =RANDBETWEEN(10,AV14) -> 17 | AV14: =RANDBETWEEN(10,50) -> 30 | AW14: =RANDBETWEEN(0,AV14*0.3) -> 3 | AX14: =RANDBETWEEN(10,AY14) -> 34 | AY14: =RANDBETWEEN(10,50) -> 40 | AZ14: =RANDBETWEEN(0,AY14*0.3) -> 9 | BA14: =RANDBETWEEN(10,BB14) -> 27 | BB14: =RANDBETWEEN(10,50) -> 37 | BC14: =RANDBETWEEN(0,BB14*0.3) -> 5 | BD14: =RANDBETWEEN(10,BE14) -> 44 | BE14: =RANDBETWEEN(10,200) -> 51 | BF14: =RANDBETWEEN(0,BE14*0.3) -> 5 | BG14: =RANDBETWEEN(10,BH14) -> 26 | BH14: =RANDBETWEEN(10,200) -> 59 | BI14: =RANDBETWEEN(0,BH14*0.3) -> 12 | BJ14: =RANDBETWEEN(10,BK14) -> 30 | BK14: =RANDBETWEEN(10,80) -> 33 | BL14: =RANDBETWEEN(0,BK14*0.3) -> 2
A15: 1011 | B15: 灵智-关羽 | C15: =RANDBETWEEN(10,50) -> 22 | D15: =RANDBETWEEN(0,1000) -> 196 | E15: =RANDBETWEEN(INDEX(Sheet1!$G:$G,MATCH('AI伪装|AIFeign'!C15,Sheet1!$E$2:$E$999,0)),INDEX(Sheet1!$G:$G,MATCH('AI伪装|AIFeign'!C15+1,Sheet1!$E:$E,0))) -> 1202 | F15: =RANDBETWEEN(1,7) -> 6 | G15: 1 | H15: =IF(INDEX(Sheet1!$A$1:$A$40,MATCH(RANDBETWEEN(1,40),Sheet1!$B$1:$B$40,0))<>1020305,INDEX(Sheet1!$A$1:$A$40,MATCH(RANDBETWEEN(1,40),Sheet1!$B$1:$B$40,0)),1020303) -> 1020004 | I15: =RANDBETWEEN(-200,2000) -> 1387 | J15: =RANDBETWEEN(20,20000) -> 2183 | K15: =RANDBETWEEN(10,L15) -> 255 | L15: =RANDBETWEEN(10,600) -> 296 | M15: =RANDBETWEEN(0,L15*0.3) -> 4 | N15: =RANDBETWEEN(0,O15) -> 100 | O15: =MAX(RANDBETWEEN(L15-50,L15+50),0) -> 298 | P15: =RANDBETWEEN(0,O15*0.3) -> 4 | Q15: =RANDBETWEEN(10,R15) -> 16 | R15: =RANDBETWEEN(10,100) -> 73 | S15: =RANDBETWEEN(0,R15*0.3) -> 12 | T15: =RANDBETWEEN(10,U15) -> 15 | U15: =RANDBETWEEN(10,100) -> 27 | V15: =RANDBETWEEN(0,U15*0.3) -> 7 | W15: =RANDBETWEEN(10,X15) -> 33 | X15: =RANDBETWEEN(10,100) -> 34 | Y15: =RANDBETWEEN(0,X15*0.3) -> 9 | Z15: =RANDBETWEEN(10,AA15) -> 72 | AA15: =RANDBETWEEN(10,100) -> 80 | AB15: =RANDBETWEEN(0,AA15*0.3) -> 9 | AC15: =RANDBETWEEN(0,AD15) -> 114 | AD15: =RANDBETWEEN(R15*2-R15,R15*2+R15) -> 180 | AE15: =RANDBETWEEN(0,AD15*0.3) -> 51 | AF15: =RANDBETWEEN(10,AG15) -> 28 | AG15: =RANDBETWEEN(10,50) -> 33 | AH15: =RANDBETWEEN(0,AG15*0.3) -> 6 | AI15: =RANDBETWEEN(10,AJ15) -> 10 | AJ15: =RANDBETWEEN(10,50) -> 15 | AK15: =RANDBETWEEN(0,AJ15*0.3) -> 1 | AL15: =RANDBETWEEN(10,AM15) -> 10 | AM15: =RANDBETWEEN(10,50) -> 31 | AN15: =RANDBETWEEN(0,AM15*0.3) -> 8 | AO15: =RANDBETWEEN(10,AP15) -> 106 | AP15: =RANDBETWEEN(AD15*4-AD15,AD15*4+AD15) -> 686 | AQ15: =RANDBETWEEN(0,AP15*0.3) -> 198 | AR15: =RANDBETWEEN(10,AS15) -> 40 | AS15: =RANDBETWEEN(10,50) -> 45 | AT15: =RANDBETWEEN(0,AS15*0.3) -> 8 | AU15: =RANDBETWEEN(10,AV15) -> 28 | AV15: =RANDBETWEEN(10,50) -> 39 | AW15: =RANDBETWEEN(0,AV15*0.3) -> 10 | AX15: =RANDBETWEEN(10,AY15) -> 25 | AY15: =RANDBETWEEN(10,50) -> 49 | AZ15: =RANDBETWEEN(0,AY15*0.3) -> 13 | BA15: =RANDBETWEEN(10,BB15) -> 17 | BB15: =RANDBETWEEN(10,50) -> 24 | BC15: =RANDBETWEEN(0,BB15*0.3) -> 1 | BD15: =RANDBETWEEN(10,BE15) -> 69 | BE15: =RANDBETWEEN(10,200) -> 102 | BF15: =RANDBETWEEN(0,BE15*0.3) -> 22 | BG15: =RANDBETWEEN(10,BH15) -> 20 | BH15: =RANDBETWEEN(10,200) -> 57 | BI15: =RANDBETWEEN(0,BH15*0.3) -> 7 | BJ15: =RANDBETWEEN(10,BK15) -> 19 | BK15: =RANDBETWEEN(10,80) -> 31 | BL15: =RANDBETWEEN(0,BK15*0.3) -> 4
A16: 1012 | B16: 灵智-张飞 | C16: =RANDBETWEEN(10,50) -> 24 | D16: =RANDBETWEEN(0,1000) -> 252 | E16: =RANDBETWEEN(INDEX(Sheet1!$G:$G,MATCH('AI伪装|AIFeign'!C16,Sheet1!$E$2:$E$999,0)),INDEX(Sheet1!$G:$G,MATCH('AI伪装|AIFeign'!C16+1,Sheet1!$E:$E,0))) -> 1985 | F16: =RANDBETWEEN(1,7) -> 6 | G16: 1 | H16: =IF(INDEX(Sheet1!$A$1:$A$40,MATCH(RANDBETWEEN(1,40),Sheet1!$B$1:$B$40,0))<>1020305,INDEX(Sheet1!$A$1:$A$40,MATCH(RANDBETWEEN(1,40),Sheet1!$B$1:$B$40,0)),1020303) -> 1020207 | I16: =RANDBETWEEN(-200,2000) -> 1153 | J16: =RANDBETWEEN(20,20000) -> 13865 | K16: =RANDBETWEEN(10,L16) -> 68 | L16: =RANDBETWEEN(10,600) -> 559 | M16: =RANDBETWEEN(0,L16*0.3) -> 146 | N16: =RANDBETWEEN(0,O16) -> 197 | O16: =MAX(RANDBETWEEN(L16-50,L16+50),0) -> 528 | P16: =RANDBETWEEN(0,O16*0.3) -> 21 | Q16: =RANDBETWEEN(10,R16) -> 12 | R16: =RANDBETWEEN(10,100) -> 15 | S16: =RANDBETWEEN(0,R16*0.3) -> 1 | T16: =RANDBETWEEN(10,U16) -> 44 | U16: =RANDBETWEEN(10,100) -> 68 | V16: =RANDBETWEEN(0,U16*0.3) -> 16 | W16: =RANDBETWEEN(10,X16) -> 47 | X16: =RANDBETWEEN(10,100) -> 73 | Y16: =RANDBETWEEN(0,X16*0.3) -> 18 | Z16: =RANDBETWEEN(10,AA16) -> 33 | AA16: =RANDBETWEEN(10,100) -> 34 | AB16: =RANDBETWEEN(0,AA16*0.3) -> 10 | AC16: =RANDBETWEEN(0,AD16) -> 18 | AD16: =RANDBETWEEN(R16*2-R16,R16*2+R16) -> 21 | AE16: =RANDBETWEEN(0,AD16*0.3) -> 1 | AF16: =RANDBETWEEN(10,AG16) -> 11 | AG16: =RANDBETWEEN(10,50) -> 20 | AH16: =RANDBETWEEN(0,AG16*0.3) -> 6 | AI16: =RANDBETWEEN(10,AJ16) -> 14 | AJ16: =RANDBETWEEN(10,50) -> 36 | AK16: =RANDBETWEEN(0,AJ16*0.3) -> 2 | AL16: =RANDBETWEEN(10,AM16) -> 39 | AM16: =RANDBETWEEN(10,50) -> 44 | AN16: =RANDBETWEEN(0,AM16*0.3) -> 2 | AO16: =RANDBETWEEN(10,AP16) -> 63 | AP16: =RANDBETWEEN(AD16*4-AD16,AD16*4+AD16) -> 93 | AQ16: =RANDBETWEEN(0,AP16*0.3) -> 19 | AR16: =RANDBETWEEN(10,AS16) -> 16 | AS16: =RANDBETWEEN(10,50) -> 28 | AT16: =RANDBETWEEN(0,AS16*0.3) -> 0 | AU16: =RANDBETWEEN(10,AV16) -> 31 | AV16: =RANDBETWEEN(10,50) -> 33 | AW16: =RANDBETWEEN(0,AV16*0.3) -> 5 | AX16: =RANDBETWEEN(10,AY16) -> 17 | AY16: =RANDBETWEEN(10,50) -> 31 | AZ16: =RANDBETWEEN(0,AY16*0.3) -> 9 | BA16: =RANDBETWEEN(10,BB16) -> 25 | BB16: =RANDBETWEEN(10,50) -> 38 | BC16: =RANDBETWEEN(0,BB16*0.3) -> 9 | BD16: =RANDBETWEEN(10,BE16) -> 20 | BE16: =RANDBETWEEN(10,200) -> 155 | BF16: =RANDBETWEEN(0,BE16*0.3) -> 25 | BG16: =RANDBETWEEN(10,BH16) -> 130 | BH16: =RANDBETWEEN(10,200) -> 155 | BI16: =RANDBETWEEN(0,BH16*0.3) -> 46 | BJ16: =RANDBETWEEN(10,BK16) -> 45 | BK16: =RANDBETWEEN(10,80) -> 52 | BL16: =RANDBETWEEN(0,BK16*0.3) -> 13
... A211: 1207 | B211: 灵智-扁鹊 | C211: =RANDBETWEEN(10,50) -> 28 | D211: =RANDBETWEEN(0,1000) -> 353 | E211: =RANDBETWEEN(INDEX(Sheet1!$G:$G,MATCH('AI伪装|AIFeign'!C211,Sheet1!$E$2:$E$999,0)),INDEX(Sheet1!$G:$G,MATCH('AI伪装|AIFeign'!C211+1,Sheet1!$E:$E,0))) -> 3166 | F211: =RANDBETWEEN(1,7) -> 3 | G211: 1 | H211: =IF(INDEX(Sheet1!$A$1:$A$40,MATCH(RANDBETWEEN(1,40),Sheet1!$B$1:$B$40,0))<>1020305,INDEX(Sheet1!$A$1:$A$40,MATCH(RANDBETWEEN(1,40),Sheet1!$B$1:$B$40,0)),1020303) -> 1020002 | I211: =RANDBETWEEN(-200,2000) -> 1325 | J211: =RANDBETWEEN(20,20000) -> 15913 | K211: =RANDBETWEEN(10,L211) -> 86 | L211: =RANDBETWEEN(10,600) -> 110 | M211: =RANDBETWEEN(0,L211*0.3) -> 23 | N211: =RANDBETWEEN(0,O211) -> 74 | O211: =MAX(RANDBETWEEN(L211-50,L211+50),0) -> 75 | P211: =RANDBETWEEN(0,O211*0.3) -> 21 | Q211: =RANDBETWEEN(10,R211) -> 48 | R211: =RANDBETWEEN(10,100) -> 57 | S211: =RANDBETWEEN(0,R211*0.3) -> 7 | T211: =RANDBETWEEN(10,U211) -> 12 | U211: =RANDBETWEEN(10,100) -> 12 | V211: =RANDBETWEEN(0,U211*0.3) -> 1 | W211: =RANDBETWEEN(10,X211) -> 10 | X211: =RANDBETWEEN(10,100) -> 57 | Y211: =RANDBETWEEN(0,X211*0.3) -> 16 | Z211: =RANDBETWEEN(10,AA211) -> 20 | AA211: =RANDBETWEEN(10,100) -> 70 | AB211: =RANDBETWEEN(0,AA211*0.3) -> 0 | AC211: =RANDBETWEEN(0,AD211) -> 6 | AD211: =RANDBETWEEN(R211*2-R211,R211*2+R211) -> 60 | AE211: =RANDBETWEEN(0,AD211*0.3) -> 14 | AF211: =RANDBETWEEN(10,AG211) -> 15 | AG211: =RANDBETWEEN(10,50) -> 18 | AH211: =RANDBETWEEN(0,AG211*0.3) -> 4 | AI211: =RANDBETWEEN(10,AJ211) -> 38 | AJ211: =RANDBETWEEN(10,50) -> 43 | AK211: =RANDBETWEEN(0,AJ211*0.3) -> 11 | AL211: =RANDBETWEEN(10,AM211) -> 26 | AM211: =RANDBETWEEN(10,50) -> 36 | AN211: =RANDBETWEEN(0,AM211*0.3) -> 2 | AO211: =RANDBETWEEN(10,AP211) -> 100 | AP211: =RANDBETWEEN(AD211*4-AD211,AD211*4+AD211) -> 233 | AQ211: =RANDBETWEEN(0,AP211*0.3) -> 2 | AR211: =RANDBETWEEN(10,AS211) -> 28 | AS211: =RANDBETWEEN(10,50) -> 33 | AT211: =RANDBETWEEN(0,AS211*0.3) -> 7 | AU211: =RANDBETWEEN(10,AV211) -> 18 | AV211: =RANDBETWEEN(10,50) -> 35 | AW211: =RANDBETWEEN(0,AV211*0.3) -> 7 | AX211: =RANDBETWEEN(10,AY211) -> 19 | AY211: =RANDBETWEEN(10,50) -> 31 | AZ211: =RANDBETWEEN(0,AY211*0.3) -> 0 | BA211: =RANDBETWEEN(10,BB211) -> 24 | BB211: =RANDBETWEEN(10,50) -> 25 | BC211: =RANDBETWEEN(0,BB211*0.3) -> 2 | BD211: =RANDBETWEEN(10,BE211) -> 14 | BE211: =RANDBETWEEN(10,200) -> 14 | BF211: =RANDBETWEEN(0,BE211*0.3) -> 3 | BG211: =RANDBETWEEN(10,BH211) -> 14 | BH211: =RANDBETWEEN(10,200) -> 80 | BI211: =RANDBETWEEN(0,BH211*0.3) -> 17 | BJ211: =RANDBETWEEN(10,BK211) -> 48 | BK211: =RANDBETWEEN(10,80) -> 65 | BL211: =RANDBETWEEN(0,BK211*0.3) -> 6
A212: 2001 | B212: =INDEX(Sheet1!$K:$K,MATCH(RANDBETWEEN(1,185),Sheet1!$J:$J,0))&Sheet1!N1 -> 钜鹿曹操 | C212: =RANDBETWEEN(10,50) -> 14 | D212: =RANDBETWEEN(0,1000) -> 783 | E212: =RANDBETWEEN(INDEX(Sheet1!$G:$G,MATCH('AI伪装|AIFeign'!C212,Sheet1!$E$2:$E$999,0)),INDEX(Sheet1!$G:$G,MATCH('AI伪装|AIFeign'!C212+1,Sheet1!$E:$E,0))) -> 415 | F212: =RANDBETWEEN(1,7) -> 6 | G212: 1 | H212: =IF(INDEX(Sheet1!$A$1:$A$40,MATCH(RANDBETWEEN(1,40),Sheet1!$B$1:$B$40,0))<>1020305,INDEX(Sheet1!$A$1:$A$40,MATCH(RANDBETWEEN(1,40),Sheet1!$B$1:$B$40,0)),1020303) -> 1020302 | I212: =RANDBETWEEN(-200,2000) -> -117 | J212: =RANDBETWEEN(20,20000) -> 16449 | K212: =RANDBETWEEN(10,L212) -> 249 | L212: =RANDBETWEEN(10,600) -> 393 | M212: =RANDBETWEEN(0,L212*0.3) -> 103 | N212: =RANDBETWEEN(0,O212) -> 125 | O212: =MAX(RANDBETWEEN(L212-50,L212+50),0) -> 371 | P212: =RANDBETWEEN(0,O212*0.3) -> 110 | Q212: =RANDBETWEEN(10,R212) -> 10 | R212: =RANDBETWEEN(10,100) -> 33 | S212: =RANDBETWEEN(0,R212*0.3) -> 8 | T212: =RANDBETWEEN(10,U212) -> 18 | U212: =RANDBETWEEN(10,100) -> 20 | V212: =RANDBETWEEN(0,U212*0.3) -> 4 | W212: =RANDBETWEEN(10,X212) -> 88 | X212: =RANDBETWEEN(10,100) -> 89 | Y212: =RANDBETWEEN(0,X212*0.3) -> 13 | Z212: =RANDBETWEEN(10,AA212) -> 10 | AA212: =RANDBETWEEN(10,100) -> 79 | AB212: =RANDBETWEEN(0,AA212*0.3) -> 12 | AC212: =RANDBETWEEN(0,AD212) -> 31 | AD212: =RANDBETWEEN(R212*2-R212,R212*2+R212) -> 64 | AE212: =RANDBETWEEN(0,AD212*0.3) -> 11 | AF212: =RANDBETWEEN(10,AG212) -> 16 | AG212: =RANDBETWEEN(10,50) -> 23 | AH212: =RANDBETWEEN(0,AG212*0.3) -> 2 | AI212: =RANDBETWEEN(10,AJ212) -> 15 | AJ212: =RANDBETWEEN(10,50) -> 17 | AK212: =RANDBETWEEN(0,AJ212*0.3) -> 2 | AL212: =RANDBETWEEN(10,AM212) -> 48 | AM212: =RANDBETWEEN(10,50) -> 49 | AN212: =RANDBETWEEN(0,AM212*0.3) -> 7 | AO212: =RANDBETWEEN(10,AP212) -> 153 | AP212: =RANDBETWEEN(AD212*4-AD212,AD212*4+AD212) -> 216 | AQ212: =RANDBETWEEN(0,AP212*0.3) -> 50 | AR212: =RANDBETWEEN(10,AS212) -> 37 | AS212: =RANDBETWEEN(10,50) -> 37 | AT212: =RANDBETWEEN(0,AS212*0.3) -> 10 | AU212: =RANDBETWEEN(10,AV212) -> 38 | AV212: =RANDBETWEEN(10,50) -> 40 | AW212: =RANDBETWEEN(0,AV212*0.3) -> 7 | AX212: =RANDBETWEEN(10,AY212) -> 31 | AY212: =RANDBETWEEN(10,50) -> 33 | AZ212: =RANDBETWEEN(0,AY212*0.3) -> 9 | BA212: =RANDBETWEEN(10,BB212) -> 36 | BB212: =RANDBETWEEN(10,50) -> 40 | BC212: =RANDBETWEEN(0,BB212*0.3) -> 2 | BD212: =RANDBETWEEN(10,BE212) -> 64 | BE212: =RANDBETWEEN(10,200) -> 129 | BF212: =RANDBETWEEN(0,BE212*0.3) -> 37 | BG212: =RANDBETWEEN(10,BH212) -> 11 | BH212: =RANDBETWEEN(10,200) -> 26 | BI212: =RANDBETWEEN(0,BH212*0.3) -> 4 | BJ212: =RANDBETWEEN(10,BK212) -> 22 | BK212: =RANDBETWEEN(10,80) -> 28 | BL212: =RANDBETWEEN(0,BK212*0.3) -> 0
A213: 2002 | B213: =INDEX(Sheet1!$K:$K,MATCH(RANDBETWEEN(1,185),Sheet1!$J:$J,0))&Sheet1!N2 -> 白马郭嘉 | C213: =RANDBETWEEN(10,50) -> 38 | D213: =RANDBETWEEN(0,1000) -> 176 | E213: =RANDBETWEEN(INDEX(Sheet1!$G:$G,MATCH('AI伪装|AIFeign'!C213,Sheet1!$E$2:$E$999,0)),INDEX(Sheet1!$G:$G,MATCH('AI伪装|AIFeign'!C213+1,Sheet1!$E:$E,0))) -> 7631 | F213: =RANDBETWEEN(1,7) -> 5 | G213: 1 | H213: =IF(INDEX(Sheet1!$A$1:$A$40,MATCH(RANDBETWEEN(1,40),Sheet1!$B$1:$B$40,0))<>1020305,INDEX(Sheet1!$A$1:$A$40,MATCH(RANDBETWEEN(1,40),Sheet1!$B$1:$B$40,0)),1020303) -> 1020001 | I213: =RANDBETWEEN(-200,2000) -> 1973 | J213: =RANDBETWEEN(20,20000) -> 17685 | K213: =RANDBETWEEN(10,L213) -> 20 | L213: =RANDBETWEEN(10,600) -> 35 | M213: =RANDBETWEEN(0,L213*0.3) -> 2 | N213: =RANDBETWEEN(0,O213) -> 56 | O213: =MAX(RANDBETWEEN(L213-50,L213+50),0) -> 78 | P213: =RANDBETWEEN(0,O213*0.3) -> 10 | Q213: =RANDBETWEEN(10,R213) -> 15 | R213: =RANDBETWEEN(10,100) -> 28 | S213: =RANDBETWEEN(0,R213*0.3) -> 5 | T213: =RANDBETWEEN(10,U213) -> 11 | U213: =RANDBETWEEN(10,100) -> 17 | V213: =RANDBETWEEN(0,U213*0.3) -> 3 | W213: =RANDBETWEEN(10,X213) -> 40 | X213: =RANDBETWEEN(10,100) -> 90 | Y213: =RANDBETWEEN(0,X213*0.3) -> 17 | Z213: =RANDBETWEEN(10,AA213) -> 53 | AA213: =RANDBETWEEN(10,100) -> 74 | AB213: =RANDBETWEEN(0,AA213*0.3) -> 13 | AC213: =RANDBETWEEN(0,AD213) -> 57 | AD213: =RANDBETWEEN(R213*2-R213,R213*2+R213) -> 73 | AE213: =RANDBETWEEN(0,AD213*0.3) -> 0 | AF213: =RANDBETWEEN(10,AG213) -> 25 | AG213: =RANDBETWEEN(10,50) -> 42 | AH213: =RANDBETWEEN(0,AG213*0.3) -> 10 | AI213: =RANDBETWEEN(10,AJ213) -> 22 | AJ213: =RANDBETWEEN(10,50) -> 23 | AK213: =RANDBETWEEN(0,AJ213*0.3) -> 5 | AL213: =RANDBETWEEN(10,AM213) -> 27 | AM213: =RANDBETWEEN(10,50) -> 29 | AN213: =RANDBETWEEN(0,AM213*0.3) -> 7 | AO213: =RANDBETWEEN(10,AP213) -> 82 | AP213: =RANDBETWEEN(AD213*4-AD213,AD213*4+AD213) -> 341 | AQ213: =RANDBETWEEN(0,AP213*0.3) -> 94 | AR213: =RANDBETWEEN(10,AS213) -> 36 | AS213: =RANDBETWEEN(10,50) -> 45 | AT213: =RANDBETWEEN(0,AS213*0.3) -> 7 | AU213: =RANDBETWEEN(10,AV213) -> 16 | AV213: =RANDBETWEEN(10,50) -> 48 | AW213: =RANDBETWEEN(0,AV213*0.3) -> 13 | AX213: =RANDBETWEEN(10,AY213) -> 10 | AY213: =RANDBETWEEN(10,50) -> 10 | AZ213: =RANDBETWEEN(0,AY213*0.3) -> 0 | BA213: =RANDBETWEEN(10,BB213) -> 14 | BB213: =RANDBETWEEN(10,50) -> 37 | BC213: =RANDBETWEEN(0,BB213*0.3) -> 0 | BD213: =RANDBETWEEN(10,BE213) -> 14 | BE213: =RANDBETWEEN(10,200) -> 26 | BF213: =RANDBETWEEN(0,BE213*0.3) -> 1 | BG213: =RANDBETWEEN(10,BH213) -> 94 | BH213: =RANDBETWEEN(10,200) -> 155 | BI213: =RANDBETWEEN(0,BH213*0.3) -> 33 | BJ213: =RANDBETWEEN(10,BK213) -> 52 | BK213: =RANDBETWEEN(10,80) -> 53 | BL213: =RANDBETWEEN(0,BK213*0.3) -> 13
A214: 2003 | B214: =INDEX(Sheet1!$K:$K,MATCH(RANDBETWEEN(1,185),Sheet1!$J:$J,0))&Sheet1!N3 -> 京兆张辽 | C214: =RANDBETWEEN(10,50) -> 22 | D214: =RANDBETWEEN(0,1000) -> 85 | E214: =RANDBETWEEN(INDEX(Sheet1!$G:$G,MATCH('AI伪装|AIFeign'!C214,Sheet1!$E$2:$E$999,0)),INDEX(Sheet1!$G:$G,MATCH('AI伪装|AIFeign'!C214+1,Sheet1!$E:$E,0))) -> 1383 | F214: =RANDBETWEEN(1,7) -> 2 | G214: 1 | H214: =IF(INDEX(Sheet1!$A$1:$A$40,MATCH(RANDBETWEEN(1,40),Sheet1!$B$1:$B$40,0))<>1020305,INDEX(Sheet1!$A$1:$A$40,MATCH(RANDBETWEEN(1,40),Sheet1!$B$1:$B$40,0)),1020303) -> 1020302 | I214: =RANDBETWEEN(-200,2000) -> 1013 | J214: =RANDBETWEEN(20,20000) -> 4768 | K214: =RANDBETWEEN(10,L214) -> 94 | L214: =RANDBETWEEN(10,600) -> 335 | M214: =RANDBETWEEN(0,L214*0.3) -> 66 | N214: =RANDBETWEEN(0,O214) -> 314 | O214: =MAX(RANDBETWEEN(L214-50,L214+50),0) -> 347 | P214: =RANDBETWEEN(0,O214*0.3) -> 11 | Q214: =RANDBETWEEN(10,R214) -> 18 | R214: =RANDBETWEEN(10,100) -> 23 | S214: =RANDBETWEEN(0,R214*0.3) -> 3 | T214: =RANDBETWEEN(10,U214) -> 63 | U214: =RANDBETWEEN(10,100) -> 81 | V214: =RANDBETWEEN(0,U214*0.3) -> 24 | W214: =RANDBETWEEN(10,X214) -> 12 | X214: =RANDBETWEEN(10,100) -> 32 | Y214: =RANDBETWEEN(0,X214*0.3) -> 0 | Z214: =RANDBETWEEN(10,AA214) -> 13 | AA214: =RANDBETWEEN(10,100) -> 20 | AB214: =RANDBETWEEN(0,AA214*0.3) -> 6 | AC214: =RANDBETWEEN(0,AD214) -> 18 | AD214: =RANDBETWEEN(R214*2-R214,R214*2+R214) -> 52 | AE214: =RANDBETWEEN(0,AD214*0.3) -> 1 | AF214: =RANDBETWEEN(10,AG214) -> 26 | AG214: =RANDBETWEEN(10,50) -> 42 | AH214: =RANDBETWEEN(0,AG214*0.3) -> 5 | AI214: =RANDBETWEEN(10,AJ214) -> 10 | AJ214: =RANDBETWEEN(10,50) -> 10 | AK214: =RANDBETWEEN(0,AJ214*0.3) -> 3 | AL214: =RANDBETWEEN(10,AM214) -> 25 | AM214: =RANDBETWEEN(10,50) -> 25 | AN214: =RANDBETWEEN(0,AM214*0.3) -> 7 | AO214: =RANDBETWEEN(10,AP214) -> 106 | AP214: =RANDBETWEEN(AD214*4-AD214,AD214*4+AD214) -> 167 | AQ214: =RANDBETWEEN(0,AP214*0.3) -> 31 | AR214: =RANDBETWEEN(10,AS214) -> 15 | AS214: =RANDBETWEEN(10,50) -> 15 | AT214: =RANDBETWEEN(0,AS214*0.3) -> 1 | AU214: =RANDBETWEEN(10,AV214) -> 24 | AV214: =RANDBETWEEN(10,50) -> 24 | AW214: =RANDBETWEEN(0,AV214*0.3) -> 6 | AX214: =RANDBETWEEN(10,AY214) -> 11 | AY214: =RANDBETWEEN(10,50) -> 11 | AZ214: =RANDBETWEEN(0,AY214*0.3) -> 3 | BA214: =RANDBETWEEN(10,BB214) -> 12 | BB214: =RANDBETWEEN(10,50) -> 13 | BC214: =RANDBETWEEN(0,BB214*0.3) -> 1 | BD214: =RANDBETWEEN(10,BE214) -> 141 | BE214: =RANDBETWEEN(10,200) -> 171 | BF214: =RANDBETWEEN(0,BE214*0.3) -> 45 | BG214: =RANDBETWEEN(10,BH214) -> 90 | BH214: =RANDBETWEEN(10,200) -> 116 | BI214: =RANDBETWEEN(0,BH214*0.3) -> 2 | BJ214: =RANDBETWEEN(10,BK214) -> 24 | BK214: =RANDBETWEEN(10,80) -> 58 | BL214: =RANDBETWEEN(0,BK214*0.3) -> 7
A215: 2004 | B215: =INDEX(Sheet1!$K:$K,MATCH(RANDBETWEEN(1,185),Sheet1!$J:$J,0))&Sheet1!N4 -> 钜鹿甄姬 | C215: =RANDBETWEEN(10,50) -> 20 | D215: =RANDBETWEEN(0,1000) -> 621 | E215: =RANDBETWEEN(INDEX(Sheet1!$G:$G,MATCH('AI伪装|AIFeign'!C215,Sheet1!$E$2:$E$999,0)),INDEX(Sheet1!$G:$G,MATCH('AI伪装|AIFeign'!C215+1,Sheet1!$E:$E,0))) -> 1051 | F215: =RANDBETWEEN(1,7) -> 5 | G215: 1 | H215: =IF(INDEX(Sheet1!$A$1:$A$40,MATCH(RANDBETWEEN(1,40),Sheet1!$B$1:$B$40,0))<>1020305,INDEX(Sheet1!$A$1:$A$40,MATCH(RANDBETWEEN(1,40),Sheet1!$B$1:$B$40,0)),1020303) -> 1020002 | I215: =RANDBETWEEN(-200,2000) -> 1889 | J215: =RANDBETWEEN(20,20000) -> 12905 | K215: =RANDBETWEEN(10,L215) -> 217 | L215: =RANDBETWEEN(10,600) -> 325 | M215: =RANDBETWEEN(0,L215*0.3) -> 61 | N215: =RANDBETWEEN(0,O215) -> 11 | O215: =MAX(RANDBETWEEN(L215-50,L215+50),0) -> 371 | P215: =RANDBETWEEN(0,O215*0.3) -> 40 | Q215: =RANDBETWEEN(10,R215) -> 42 | R215: =RANDBETWEEN(10,100) -> 59 | S215: =RANDBETWEEN(0,R215*0.3) -> 12 | T215: =RANDBETWEEN(10,U215) -> 18 | U215: =RANDBETWEEN(10,100) -> 66 | V215: =RANDBETWEEN(0,U215*0.3) -> 2 | W215: =RANDBETWEEN(10,X215) -> 10 | X215: =RANDBETWEEN(10,100) -> 16 | Y215: =RANDBETWEEN(0,X215*0.3) -> 3 | Z215: =RANDBETWEEN(10,AA215) -> 16 | AA215: =RANDBETWEEN(10,100) -> 48 | AB215: =RANDBETWEEN(0,AA215*0.3) -> 11 | AC215: =RANDBETWEEN(0,AD215) -> 33 | AD215: =RANDBETWEEN(R215*2-R215,R215*2+R215) -> 111 | AE215: =RANDBETWEEN(0,AD215*0.3) -> 20 | AF215: =RANDBETWEEN(10,AG215) -> 22 | AG215: =RANDBETWEEN(10,50) -> 31 | AH215: =RANDBETWEEN(0,AG215*0.3) -> 6 | AI215: =RANDBETWEEN(10,AJ215) -> 27 | AJ215: =RANDBETWEEN(10,50) -> 37 | AK215: =RANDBETWEEN(0,AJ215*0.3) -> 6 | AL215: =RANDBETWEEN(10,AM215) -> 24 | AM215: =RANDBETWEEN(10,50) -> 46 | AN215: =RANDBETWEEN(0,AM215*0.3) -> 11 | AO215: =RANDBETWEEN(10,AP215) -> 307 | AP215: =RANDBETWEEN(AD215*4-AD215,AD215*4+AD215) -> 416 | AQ215: =RANDBETWEEN(0,AP215*0.3) -> 120 | AR215: =RANDBETWEEN(10,AS215) -> 23 | AS215: =RANDBETWEEN(10,50) -> 48 | AT215: =RANDBETWEEN(0,AS215*0.3) -> 4 | AU215: =RANDBETWEEN(10,AV215) -> 22 | AV215: =RANDBETWEEN(10,50) -> 28 | AW215: =RANDBETWEEN(0,AV215*0.3) -> 4 | AX215: =RANDBETWEEN(10,AY215) -> 25 | AY215: =RANDBETWEEN(10,50) -> 35 | AZ215: =RANDBETWEEN(0,AY215*0.3) -> 3 | BA215: =RANDBETWEEN(10,BB215) -> 10 | BB215: =RANDBETWEEN(10,50) -> 11 | BC215: =RANDBETWEEN(0,BB215*0.3) -> 2 | BD215: =RANDBETWEEN(10,BE215) -> 19 | BE215: =RANDBETWEEN(10,200) -> 20 | BF215: =RANDBETWEEN(0,BE215*0.3) -> 6 | BG215: =RANDBETWEEN(10,BH215) -> 150 | BH215: =RANDBETWEEN(10,200) -> 177 | BI215: =RANDBETWEEN(0,BH215*0.3) -> 51 | BJ215: =RANDBETWEEN(10,BK215) -> 35 | BK215: =RANDBETWEEN(10,80) -> 73 | BL215: =RANDBETWEEN(0,BK215*0.3) -> 1
A216: 2005 | B216: =INDEX(Sheet1!$K:$K,MATCH(RANDBETWEEN(1,185),Sheet1!$J:$J,0))&Sheet1!N5 -> 巴东荀彧 | C216: =RANDBETWEEN(10,50) -> 41 | D216: =RANDBETWEEN(0,1000) -> 200 | E216: =RANDBETWEEN(INDEX(Sheet1!$G:$G,MATCH('AI伪装|AIFeign'!C216,Sheet1!$E$2:$E$999,0)),INDEX(Sheet1!$G:$G,MATCH('AI伪装|AIFeign'!C216+1,Sheet1!$E:$E,0))) -> 9898 | F216: =RANDBETWEEN(1,7) -> 2 | G216: 1 | H216: =IF(INDEX(Sheet1!$A$1:$A$40,MATCH(RANDBETWEEN(1,40),Sheet1!$B$1:$B$40,0))<>1020305,INDEX(Sheet1!$A$1:$A$40,MATCH(RANDBETWEEN(1,40),Sheet1!$B$1:$B$40,0)),1020303) -> 1020205 | I216: =RANDBETWEEN(-200,2000) -> 745 | J216: =RANDBETWEEN(20,20000) -> 11373 | K216: =RANDBETWEEN(10,L216) -> 45 | L216: =RANDBETWEEN(10,600) -> 48 | M216: =RANDBETWEEN(0,L216*0.3) -> 4 | N216: =RANDBETWEEN(0,O216) -> 24 | O216: =MAX(RANDBETWEEN(L216-50,L216+50),0) -> 44 | P216: =RANDBETWEEN(0,O216*0.3) -> 5 | Q216: =RANDBETWEEN(10,R216) -> 17 | R216: =RANDBETWEEN(10,100) -> 50 | S216: =RANDBETWEEN(0,R216*0.3) -> 8 | T216: =RANDBETWEEN(10,U216) -> 27 | U216: =RANDBETWEEN(10,100) -> 49 | V216: =RANDBETWEEN(0,U216*0.3) -> 9 | W216: =RANDBETWEEN(10,X216) -> 26 | X216: =RANDBETWEEN(10,100) -> 32 | Y216: =RANDBETWEEN(0,X216*0.3) -> 9 | Z216: =RANDBETWEEN(10,AA216) -> 11 | AA216: =RANDBETWEEN(10,100) -> 14 | AB216: =RANDBETWEEN(0,AA216*0.3) -> 1 | AC216: =RANDBETWEEN(0,AD216) -> 69 | AD216: =RANDBETWEEN(R216*2-R216,R216*2+R216) -> 71 | AE216: =RANDBETWEEN(0,AD216*0.3) -> 0 | AF216: =RANDBETWEEN(10,AG216) -> 10 | AG216: =RANDBETWEEN(10,50) -> 39 | AH216: =RANDBETWEEN(0,AG216*0.3) -> 3 | AI216: =RANDBETWEEN(10,AJ216) -> 10 | AJ216: =RANDBETWEEN(10,50) -> 28 | AK216: =RANDBETWEEN(0,AJ216*0.3) -> 3 | AL216: =RANDBETWEEN(10,AM216) -> 26 | AM216: =RANDBETWEEN(10,50) -> 27 | AN216: =RANDBETWEEN(0,AM216*0.3) -> 7 | AO216: =RANDBETWEEN(10,AP216) -> 10 | AP216: =RANDBETWEEN(AD216*4-AD216,AD216*4+AD216) -> 252 | AQ216: =RANDBETWEEN(0,AP216*0.3) -> 65 | AR216: =RANDBETWEEN(10,AS216) -> 11 | AS216: =RANDBETWEEN(10,50) -> 25 | AT216: =RANDBETWEEN(0,AS216*0.3) -> 2 | AU216: =RANDBETWEEN(10,AV216) -> 12 | AV216: =RANDBETWEEN(10,50) -> 15 | AW216: =RANDBETWEEN(0,AV216*0.3) -> 1 | AX216: =RANDBETWEEN(10,AY216) -> 39 | AY216: =RANDBETWEEN(10,50) -> 46 | AZ216: =RANDBETWEEN(0,AY216*0.3) -> 12 | BA216: =RANDBETWEEN(10,BB216) -> 16 | BB216: =RANDBETWEEN(10,50) -> 26 | BC216: =RANDBETWEEN(0,BB216*0.3) -> 2 | BD216: =RANDBETWEEN(10,BE216) -> 13 | BE216: =RANDBETWEEN(10,200) -> 155 | BF216: =RANDBETWEEN(0,BE216*0.3) -> 21 | BG216: =RANDBETWEEN(10,BH216) -> 56 | BH216: =RANDBETWEEN(10,200) -> 58 | BI216: =RANDBETWEEN(0,BH216*0.3) -> 13 | BJ216: =RANDBETWEEN(10,BK216) -> 23 | BK216: =RANDBETWEEN(10,80) -> 37 | BL216: =RANDBETWEEN(0,BK216*0.3) -> 5
A217: 2006 | B217: =INDEX(Sheet1!$K:$K,MATCH(RANDBETWEEN(1,185),Sheet1!$J:$J,0))&Sheet1!N6 -> 广阳郡许褚 | C217: =RANDBETWEEN(10,50) -> 42 | D217: =RANDBETWEEN(0,1000) -> 830 | E217: =RANDBETWEEN(INDEX(Sheet1!$G:$G,MATCH('AI伪装|AIFeign'!C217,Sheet1!$E$2:$E$999,0)),INDEX(Sheet1!$G:$G,MATCH('AI伪装|AIFeign'!C217+1,Sheet1!$E:$E,0))) -> 10724 | F217: =RANDBETWEEN(1,7) -> 6 | G217: 1 | H217: =IF(INDEX(Sheet1!$A$1:$A$40,MATCH(RANDBETWEEN(1,40),Sheet1!$B$1:$B$40,0))<>1020305,INDEX(Sheet1!$A$1:$A$40,MATCH(RANDBETWEEN(1,40),Sheet1!$B$1:$B$40,0)),1020303) -> 1020107 | I217: =RANDBETWEEN(-200,2000) -> 140 | J217: =RANDBETWEEN(20,20000) -> 2834 | K217: =RANDBETWEEN(10,L217) -> 191 | L217: =RANDBETWEEN(10,600) -> 387 | M217: =RANDBETWEEN(0,L217*0.3) -> 0 | N217: =RANDBETWEEN(0,O217) -> 164 | O217: =MAX(RANDBETWEEN(L217-50,L217+50),0) -> 359 | P217: =RANDBETWEEN(0,O217*0.3) -> 25 | Q217: =RANDBETWEEN(10,R217) -> 43 | R217: =RANDBETWEEN(10,100) -> 51 | S217: =RANDBETWEEN(0,R217*0.3) -> 0 | T217: =RANDBETWEEN(10,U217) -> 32 | U217: =RANDBETWEEN(10,100) -> 56 | V217: =RANDBETWEEN(0,U217*0.3) -> 9 | W217: =RANDBETWEEN(10,X217) -> 26 | X217: =RANDBETWEEN(10,100) -> 59 | Y217: =RANDBETWEEN(0,X217*0.3) -> 17 | Z217: =RANDBETWEEN(10,AA217) -> 64 | AA217: =RANDBETWEEN(10,100) -> 66 | AB217: =RANDBETWEEN(0,AA217*0.3) -> 19 | AC217: =RANDBETWEEN(0,AD217) -> 119 | AD217: =RANDBETWEEN(R217*2-R217,R217*2+R217) -> 131 | AE217: =RANDBETWEEN(0,AD217*0.3) -> 32 | AF217: =RANDBETWEEN(10,AG217) -> 37 | AG217: =RANDBETWEEN(10,50) -> 44 | AH217: =RANDBETWEEN(0,AG217*0.3) -> 5 | AI217: =RANDBETWEEN(10,AJ217) -> 37 | AJ217: =RANDBETWEEN(10,50) -> 42 | AK217: =RANDBETWEEN(0,AJ217*0.3) -> 12 | AL217: =RANDBETWEEN(10,AM217) -> 15 | AM217: =RANDBETWEEN(10,50) -> 15 | AN217: =RANDBETWEEN(0,AM217*0.3) -> 0 | AO217: =RANDBETWEEN(10,AP217) -> 445 | AP217: =RANDBETWEEN(AD217*4-AD217,AD217*4+AD217) -> 582 | AQ217: =RANDBETWEEN(0,AP217*0.3) -> 0 | AR217: =RANDBETWEEN(10,AS217) -> 15 | AS217: =RANDBETWEEN(10,50) -> 21 | AT217: =RANDBETWEEN(0,AS217*0.3) -> 1 | AU217: =RANDBETWEEN(10,AV217) -> 21 | AV217: =RANDBETWEEN(10,50) -> 29 | AW217: =RANDBETWEEN(0,AV217*0.3) -> 8 | AX217: =RANDBETWEEN(10,AY217) -> 10 | AY217: =RANDBETWEEN(10,50) -> 21 | AZ217: =RANDBETWEEN(0,AY217*0.3) -> 1 | BA217: =RANDBETWEEN(10,BB217) -> 38 | BB217: =RANDBETWEEN(10,50) -> 43 | BC217: =RANDBETWEEN(0,BB217*0.3) -> 11 | BD217: =RANDBETWEEN(10,BE217) -> 22 | BE217: =RANDBETWEEN(10,200) -> 24 | BF217: =RANDBETWEEN(0,BE217*0.3) -> 0 | BG217: =RANDBETWEEN(10,BH217) -> 20 | BH217: =RANDBETWEEN(10,200) -> 45 | BI217: =RANDBETWEEN(0,BH217*0.3) -> 6 | BJ217: =RANDBETWEEN(10,BK217) -> 28 | BK217: =RANDBETWEEN(10,80) -> 29 | BL217: =RANDBETWEEN(0,BK217*0.3) -> 1
A218: 2007 | B218: =INDEX(Sheet1!$K:$K,MATCH(RANDBETWEEN(1,185),Sheet1!$J:$J,0))&Sheet1!N7 -> 交趾司马懿 | C218: =RANDBETWEEN(10,50) -> 10 | D218: =RANDBETWEEN(0,1000) -> 564 | E218: =RANDBETWEEN(INDEX(Sheet1!$G:$G,MATCH('AI伪装|AIFeign'!C218,Sheet1!$E$2:$E$999,0)),INDEX(Sheet1!$G:$G,MATCH('AI伪装|AIFeign'!C218+1,Sheet1!$E:$E,0))) -> 183 | F218: =RANDBETWEEN(1,7) -> 2 | G218: 1 | H218: =IF(INDEX(Sheet1!$A$1:$A$40,MATCH(RANDBETWEEN(1,40),Sheet1!$B$1:$B$40,0))<>1020305,INDEX(Sheet1!$A$1:$A$40,MATCH(RANDBETWEEN(1,40),Sheet1!$B$1:$B$40,0)),1020303) -> 1020307 | I218: =RANDBETWEEN(-200,2000) -> 410 | J218: =RANDBETWEEN(20,20000) -> 16990 | K218: =RANDBETWEEN(10,L218) -> 207 | L218: =RANDBETWEEN(10,600) -> 292 | M218: =RANDBETWEEN(0,L218*0.3) -> 59 | N218: =RANDBETWEEN(0,O218) -> 104 | O218: =MAX(RANDBETWEEN(L218-50,L218+50),0) -> 279 | P218: =RANDBETWEEN(0,O218*0.3) -> 66 | Q218: =RANDBETWEEN(10,R218) -> 16 | R218: =RANDBETWEEN(10,100) -> 20 | S218: =RANDBETWEEN(0,R218*0.3) -> 0 | T218: =RANDBETWEEN(10,U218) -> 69 | U218: =RANDBETWEEN(10,100) -> 79 | V218: =RANDBETWEEN(0,U218*0.3) -> 11 | W218: =RANDBETWEEN(10,X218) -> 42 | X218: =RANDBETWEEN(10,100) -> 57 | Y218: =RANDBETWEEN(0,X218*0.3) -> 9 | Z218: =RANDBETWEEN(10,AA218) -> 41 | AA218: =RANDBETWEEN(10,100) -> 62 | AB218: =RANDBETWEEN(0,AA218*0.3) -> 15 | AC218: =RANDBETWEEN(0,AD218) -> 9 | AD218: =RANDBETWEEN(R218*2-R218,R218*2+R218) -> 35 | AE218: =RANDBETWEEN(0,AD218*0.3) -> 10 | AF218: =RANDBETWEEN(10,AG218) -> 35 | AG218: =RANDBETWEEN(10,50) -> 44 | AH218: =RANDBETWEEN(0,AG218*0.3) -> 6 | AI218: =RANDBETWEEN(10,AJ218) -> 35 | AJ218: =RANDBETWEEN(10,50) -> 50 | AK218: =RANDBETWEEN(0,AJ218*0.3) -> 6 | AL218: =RANDBETWEEN(10,AM218) -> 15 | AM218: =RANDBETWEEN(10,50) -> 20 | AN218: =RANDBETWEEN(0,AM218*0.3) -> 2 | AO218: =RANDBETWEEN(10,AP218) -> 97 | AP218: =RANDBETWEEN(AD218*4-AD218,AD218*4+AD218) -> 119 | AQ218: =RANDBETWEEN(0,AP218*0.3) -> 21 | AR218: =RANDBETWEEN(10,AS218) -> 18 | AS218: =RANDBETWEEN(10,50) -> 41 | AT218: =RANDBETWEEN(0,AS218*0.3) -> 11 | AU218: =RANDBETWEEN(10,AV218) -> 40 | AV218: =RANDBETWEEN(10,50) -> 46 | AW218: =RANDBETWEEN(0,AV218*0.3) -> 6 | AX218: =RANDBETWEEN(10,AY218) -> 10 | AY218: =RANDBETWEEN(10,50) -> 13 | AZ218: =RANDBETWEEN(0,AY218*0.3) -> 1 | BA218: =RANDBETWEEN(10,BB218) -> 26 | BB218: =RANDBETWEEN(10,50) -> 32 | BC218: =RANDBETWEEN(0,BB218*0.3) -> 2 | BD218: =RANDBETWEEN(10,BE218) -> 10 | BE218: =RANDBETWEEN(10,200) -> 11 | BF218: =RANDBETWEEN(0,BE218*0.3) -> 0 | BG218: =RANDBETWEEN(10,BH218) -> 14 | BH218: =RANDBETWEEN(10,200) -> 42 | BI218: =RANDBETWEEN(0,BH218*0.3) -> 0 | BJ218: =RANDBETWEEN(10,BK218) -> 23 | BK218: =RANDBETWEEN(10,80) -> 69 | BL218: =RANDBETWEEN(0,BK218*0.3) -> 2
A219: 2008 | B219: =INDEX(Sheet1!$K:$K,MATCH(RANDBETWEEN(1,185),Sheet1!$J:$J,0))&Sheet1!N8 -> 桂林典韦 | C219: =RANDBETWEEN(10,50) -> 23 | D219: =RANDBETWEEN(0,1000) -> 469 | E219: =RANDBETWEEN(INDEX(Sheet1!$G:$G,MATCH('AI伪装|AIFeign'!C219,Sheet1!$E$2:$E$999,0)),INDEX(Sheet1!$G:$G,MATCH('AI伪装|AIFeign'!C219+1,Sheet1!$E:$E,0))) -> 1404 | F219: =RANDBETWEEN(1,7) -> 1 | G219: 1 | H219: =IF(INDEX(Sheet1!$A$1:$A$40,MATCH(RANDBETWEEN(1,40),Sheet1!$B$1:$B$40,0))<>1020305,INDEX(Sheet1!$A$1:$A$40,MATCH(RANDBETWEEN(1,40),Sheet1!$B$1:$B$40,0)),1020303) -> 1020005 | I219: =RANDBETWEEN(-200,2000) -> 949 | J219: =RANDBETWEEN(20,20000) -> 11725 | K219: =RANDBETWEEN(10,L219) -> 365 | L219: =RANDBETWEEN(10,600) -> 440 | M219: =RANDBETWEEN(0,L219*0.3) -> 75 | N219: =RANDBETWEEN(0,O219) -> 466 | O219: =MAX(RANDBETWEEN(L219-50,L219+50),0) -> 487 | P219: =RANDBETWEEN(0,O219*0.3) -> 124 | Q219: =RANDBETWEEN(10,R219) -> 13 | R219: =RANDBETWEEN(10,100) -> 68 | S219: =RANDBETWEEN(0,R219*0.3) -> 20 | T219: =RANDBETWEEN(10,U219) -> 63 | U219: =RANDBETWEEN(10,100) -> 68 | V219: =RANDBETWEEN(0,U219*0.3) -> 2 | W219: =RANDBETWEEN(10,X219) -> 10 | X219: =RANDBETWEEN(10,100) -> 10 | Y219: =RANDBETWEEN(0,X219*0.3) -> 3 | Z219: =RANDBETWEEN(10,AA219) -> 83 | AA219: =RANDBETWEEN(10,100) -> 92 | AB219: =RANDBETWEEN(0,AA219*0.3) -> 6 | AC219: =RANDBETWEEN(0,AD219) -> 64 | AD219: =RANDBETWEEN(R219*2-R219,R219*2+R219) -> 152 | AE219: =RANDBETWEEN(0,AD219*0.3) -> 5 | AF219: =RANDBETWEEN(10,AG219) -> 10 | AG219: =RANDBETWEEN(10,50) -> 14 | AH219: =RANDBETWEEN(0,AG219*0.3) -> 3 | AI219: =RANDBETWEEN(10,AJ219) -> 23 | AJ219: =RANDBETWEEN(10,50) -> 50 | AK219: =RANDBETWEEN(0,AJ219*0.3) -> 13 | AL219: =RANDBETWEEN(10,AM219) -> 42 | AM219: =RANDBETWEEN(10,50) -> 45 | AN219: =RANDBETWEEN(0,AM219*0.3) -> 10 | AO219: =RANDBETWEEN(10,AP219) -> 481 | AP219: =RANDBETWEEN(AD219*4-AD219,AD219*4+AD219) -> 687 | AQ219: =RANDBETWEEN(0,AP219*0.3) -> 154 | AR219: =RANDBETWEEN(10,AS219) -> 16 | AS219: =RANDBETWEEN(10,50) -> 21 | AT219: =RANDBETWEEN(0,AS219*0.3) -> 0 | AU219: =RANDBETWEEN(10,AV219) -> 19 | AV219: =RANDBETWEEN(10,50) -> 22 | AW219: =RANDBETWEEN(0,AV219*0.3) -> 3 | AX219: =RANDBETWEEN(10,AY219) -> 27 | AY219: =RANDBETWEEN(10,50) -> 27 | AZ219: =RANDBETWEEN(0,AY219*0.3) -> 6 | BA219: =RANDBETWEEN(10,BB219) -> 20 | BB219: =RANDBETWEEN(10,50) -> 22 | BC219: =RANDBETWEEN(0,BB219*0.3) -> 1 | BD219: =RANDBETWEEN(10,BE219) -> 74 | BE219: =RANDBETWEEN(10,200) -> 191 | BF219: =RANDBETWEEN(0,BE219*0.3) -> 25 | BG219: =RANDBETWEEN(10,BH219) -> 18 | BH219: =RANDBETWEEN(10,200) -> 57 | BI219: =RANDBETWEEN(0,BH219*0.3) -> 8 | BJ219: =RANDBETWEEN(10,BK219) -> 15 | BK219: =RANDBETWEEN(10,80) -> 17 | BL219: =RANDBETWEEN(0,BK219*0.3) -> 2
